Workbook

Sheet PRE-procesing
A1: Pregnancies | B1: Glucose | C1: BloodPressure | D1: SkinThickness | E1: Insulin | F1: BMI | G1: DiabetesPedigreeFunction | H1: Age | I1: Outcome | K1: MISSING VALUE | O1: Glucose_clean | P1: BP_clean | Q1: ST_clean | R1: Insulin_clean | S1: BMI_clean
A2: 6 | B2: 148 | C2: 72 | D2: 35 | E2: 0 | F2: 33.6 | G2: 0.627 | H2: 50 | I2: 1 | K2: Atribute | L2: Jumlah Nilai 0 | O2: =IF(B2=0,$L$11,B2) -> 148 | P2: =IF(C2=0,$L$12,C2) -> 72 | Q2: =IF(D2=0,$L$13,D2) -> 35 | R2: =IF(E2=0,$L$14,E2) -> 30.5 | S2: =IF(F2=0,$L$15,F2) -> 33.6
A3: 1 | B3: 85 | C3: 66 | D3: 29 | E3: 0 | F3: 26.6 | G3: 0.351 | H3: 31 | I3: 0 | K3: Glucose | L3: =COUNTIF(B3:B769,0) -> 5 | O3: =IF(B3=0,$L$11,B3) -> 85 | P3: =IF(C3=0,$L$12,C3) -> 66 | Q3: =IF(D3=0,$L$13,D3) -> 29 | R3: =IF(E3=0,$L$14,E3) -> 30.5 | S3: =IF(F3=0,$L$15,F3) -> 26.6
A4: 8 | B4: 183 | C4: 64 | D4: 0 | E4: 0 | F4: 23.3 | G4: 0.672 | H4: 32 | I4: 1 | K4: BloodPressure | L4: =COUNTIF(C3:C769,0) -> 35 | O4: =IF(B4=0,$L$11,B4) -> 183 | P4: =IF(C4=0,$L$12,C4) -> 64 | Q4: =IF(D4=0,$L$13,D4) -> 23 | R4: =IF(E4=0,$L$14,E4) -> 30.5 | S4: =IF(F4=0,$L$15,F4) -> 23.3
A5: 1 | B5: 89 | C5: 66 | D5: 23 | E5: 94 | F5: 28.1 | G5: 0.167 | H5: 21 | I5: 0 | K5: SkinThickness | L5: =COUNTIF(D3:D769,0) -> 227 | O5: =IF(B5=0,$L$11,B5) -> 89 | P5: =IF(C5=0,$L$12,C5) -> 66 | Q5: =IF(D5=0,$L$13,D5) -> 23 | R5: =IF(E5=0,$L$14,E5) -> 94 | S5: =IF(F5=0,$L$15,F5) -> 28.1
A6: 0 | B6: 137 | C6: 40 | D6: 35 | E6: 168 | F6: 43.1 | G6: 2.288 | H6: 33 | I6: 1 | K6: Insulin | L6: 374 | O6: =IF(B6=0,$L$11,B6) -> 137 | P6: =IF(C6=0,$L$12,C6) -> 40 | Q6: =IF(D6=0,$L$13,D6) -> 35 | R6: =IF(E6=0,$L$14,E6) -> 168 | S6: =IF(F6=0,$L$15,F6) -> 43.1
A7: 5 | B7: 116 | C7: 74 | D7: 0 | E7: 0 | F7: 25.6 | G7: 0.201 | H7: 30 | I7: 0 | K7: BMI | L7: =COUNTIF(F4:F769,0) -> 11 | O7: =IF(B7=0,$L$11,B7) -> 116 | P7: =IF(C7=0,$L$12,C7) -> 74 | Q7: =IF(D7=0,$L$13,D7) -> 23 | R7: =IF(E7=0,$L$14,E7) -> 30.5 | S7: =IF(F7=0,$L$15,F7) -> 25.6
A8: 3 | B8: 78 | C8: 50 | D8: 32 | E8: 88 | F8: 31 | G8: 0.248 | H8: 26 | I8: 1 | O8: =IF(B8=0,$L$11,B8) -> 78 | P8: =IF(C8=0,$L$12,C8) -> 50 | Q8: =IF(D8=0,$L$13,D8) -> 32 | R8: =IF(E8=0,$L$14,E8) -> 88 | S8: =IF(F8=0,$L$15,F8) -> 31
A9: 10 | B9: 115 | C9: 0 | D9: 0 | E9: 0 | F9: 35.3 | G9: 0.134 | H9: 29 | I9: 0 | K9: MEDIAN TIAP ATRIBUT | O9: =IF(B9=0,$L$11,B9) -> 115 | P9: =IF(C9=0,$L$12,C9) -> 72 | Q9: =IF(D9=0,$L$13,D9) -> 23 | R9: =IF(E9=0,$L$14,E9) -> 30.5 | S9: =IF(F9=0,$L$15,F9) -> 35.3
A10: 2 | B10: 197 | C10: 70 | D10: 45 | E10: 543 | F10: 30.5 | G10: 0.158 | H10: 53 | I10: 1 | K10: Atribute | L10: Median | O10: =IF(B10=0,$L$11,B10) -> 197 | P10: =IF(C10=0,$L$12,C10) -> 70 | Q10: =IF(D10=0,$L$13,D10) -> 45 | R10: =IF(E10=0,$L$14,E10) -> 543 | S10: =IF(F10=0,$L$15,F10) -> 30.5
A11: 8 | B11: 125 | C11: 96 | D11: 0 | E11: 0 | F11: 0 | G11: 0.232 | H11: 54 | I11: 1 | K11: Glucose | L11: =MEDIAN(B2:B769) -> 117 | O11: =IF(B11=0,$L$11,B11) -> 125 | P11: =IF(C11=0,$L$12,C11) -> 96 | Q11: =IF(D11=0,$L$13,D11) -> 23 | R11: =IF(E11=0,$L$14,E11) -> 30.5 | S11: =IF(F11=0,$L$15,F11) -> 32
A12: 4 | B12: 110 | C12: 92 | D12: 0 | E12: 0 | F12: 37.6 | G12: 0.191 | H12: 30 | I12: 0 | K12: BloodPressure | L12: =MEDIAN(C2:C769) -> 72 | O12: =IF(B12=0,$L$11,B12) -> 110 | P12: =IF(C12=0,$L$12,C12) -> 92 | Q12: =IF(D12=0,$L$13,D12) -> 23 | R12: =IF(E12=0,$L$14,E12) -> 30.5 | S12: =IF(F12=0,$L$15,F12) -> 37.6
A13: 10 | B13: 168 | C13: 74 | D13: 0 | E13: 0 | F13: 38 | G13: 0.537 | H13: 34 | I13: 1 | K13: SkinThickness | L13: =MEDIAN(D2:D769) -> 23 | O13: =IF(B13=0,$L$11,B13) -> 168 | P13: =IF(C13=0,$L$12,C13) -> 74 | Q13: =IF(D13=0,$L$13,D13) -> 23 | R13: =IF(E13=0,$L$14,E13) -> 30.5 | S13: =IF(F13=0,$L$15,F13) -> 38
A14: 10 | B14: 139 | C14: 80 | D14: 0 | E14: 0 | F14: 27.1 | G14: 1.441 | H14: 57 | I14: 0 | K14: Insulin | L14: =MEDIAN(E2:E769) -> 30.5 | O14: =IF(B14=0,$L$11,B14) -> 139 | P14: =IF(C14=0,$L$12,C14) -> 80 | Q14: =IF(D14=0,$L$13,D14) -> 23 | R14: =IF(E14=0,$L$14,E14) -> 30.5 | S14: =IF(F14=0,$L$15,F14) -> 27.1
A15: 1 | B15: 189 | C15: 60 | D15: 23 | E15: 846 | F15: 30.1 | G15: 0.398 | H15: 59 | I15: 1 | K15: BMI | L15: =MEDIAN(F2:F769) -> 32 | O15: =IF(B15=0,$L$11,B15) -> 189 | P15: =IF(C15=0,$L$12,C15) -> 60 | Q15: =IF(D15=0,$L$13,D15) -> 23 | R15: =IF(E15=0,$L$14,E15) -> 846 | S15: =IF(F15=0,$L$15,F15) -> 30.1
A16: 5 | B16: 166 | C16: 72 | D16: 19 | E16: 175 | F16: 25.8 | G16: 0.587 | H16: 51 | I16: 1 | O16: =IF(B16=0,$L$11,B16) -> 166 | P16: =IF(C16=0,$L$12,C16) -> 72 | Q16: =IF(D16=0,$L$13,D16) -> 19 | R16: =IF(E16=0,$L$14,E16) -> 175 | S16: =IF(F16=0,$L$15,F16) -> 25.8
A17: 7 | B17: 100 | C17: 0 | D17: 0 | E17: 0 | F17: 30 | G17: 0.484 | H17: 32 | I17: 1 | O17: =IF(B17=0,$L$11,B17) -> 100 | P17: =IF(C17=0,$L$12,C17) -> 72 | Q17: =IF(D17=0,$L$13,D17) -> 23 | R17: =IF(E17=0,$L$14,E17) -> 30.5 | S17: =IF(F17=0,$L$15,F17) -> 30
A18: 0 | B18: 118 | C18: 84 | D18: 47 | E18: 230 | F18: 45.8 | G18: 0.551 | H18: 31 | I18: 1 | O18: =IF(B18=0,$L$11,B18) -> 118 | P18: =IF(C18=0,$L$12,C18) -> 84 | Q18: =IF(D18=0,$L$13,D18) -> 47 | R18: =IF(E18=0,$L$14,E18) -> 230 | S18: =IF(F18=0,$L$15,F18) -> 45.8
A19: 7 | B19: 107 | C19: 74 | D19: 0 | E19: 0 | F19: 29.6 | G19: 0.254 | H19: 31 | I19: 1 | O19: =IF(B19=0,$L$11,B19) -> 107 | P19: =IF(C19=0,$L$12,C19) -> 74 | Q19: =IF(D19=0,$L$13,D19) -> 23 | R19: =IF(E19=0,$L$14,E19) -> 30.5 | S19: =IF(F19=0,$L$15,F19) -> 29.6
A20: 1 | B20: 103 | C20: 30 | D20: 38 | E20: 83 | F20: 43.3 | G20: 0.183 | H20: 33 | I20: 0 | O20: =IF(B20=0,$L$11,B20) -> 103 | P20: =IF(C20=0,$L$12,C20) -> 30 | Q20: =IF(D20=0,$L$13,D20) -> 38 | R20: =IF(E20=0,$L$14,E20) -> 83 | S20: =IF(F20=0,$L$15,F20) -> 43.3
A21: 1 | B21: 115 | C21: 70 | D21: 30 | E21: 96 | F21: 34.6 | G21: 0.529 | H21: 32 | I21: 1 | O21: =IF(B21=0,$L$11,B21) -> 115 | P21: =IF(C21=0,$L$12,C21) -> 70 | Q21: =IF(D21=0,$L$13,D21) -> 30 | R21: =IF(E21=0,$L$14,E21) -> 96 | S21: =IF(F21=0,$L$15,F21) -> 34.6
A22: 3 | B22: 126 | C22: 88 | D22: 41 | E22: 235 | F22: 39.3 | G22: 0.704 | H22: 27 | I22: 0 | O22: =IF(B22=0,$L$11,B22) -> 126 | P22: =IF(C22=0,$L$12,C22) -> 88 | Q22: =IF(D22=0,$L$13,D22) -> 41 | R22: =IF(E22=0,$L$14,E22) -> 235 | S22: =IF(F22=0,$L$15,F22) -> 39.3
A23: 8 | B23: 99 | C23: 84 | D23: 0 | E23: 0 | F23: 35.4 | G23: 0.388 | H23: 50 | I23: 0 | O23: =IF(B23=0,$L$11,B23) -> 99 | P23: =IF(C23=0,$L$12,C23) -> 84 | Q23: =IF(D23=0,$L$13,D23) -> 23 | R23: =IF(E23=0,$L$14,E23) -> 30.5 | S23: =IF(F23=0,$L$15,F23) -> 35.4
A24: 7 | B24: 196 | C24: 90 | D24: 0 | E24: 0 | F24: 39.8 | G24: 0.451 | H24: 41 | I24: 1 | O24: =IF(B24=0,$L$11,B24) -> 196 | P24: =IF(C24=0,$L$12,C24) -> 90 | Q24: =IF(D24=0,$L$13,D24) -> 23 | R24: =IF(E24=0,$L$14,E24) -> 30.5 | S24: =IF(F24=0,$L$15,F24) -> 39.8
A25: 9 | B25: 119 | C25: 80 | D25: 35 | E25: 0 | F25: 29 | G25: 0.263 | H25: 29 | I25: 1 | O25: =IF(B25=0,$L$11,B25) -> 119 | P25: =IF(C25=0,$L$12,C25) -> 80 | Q25: =IF(D25=0,$L$13,D25) -> 35 | R25: =IF(E25=0,$L$14,E25) -> 30.5 | S25: =IF(F25=0,$L$15,F25) -> 29
A26: 11 | B26: 143 | C26: 94 | D26: 33 | E26: 146 | F26: 36.6 | G26: 0.254 | H26: 51 | I26: 1 | O26: =IF(B26=0,$L$11,B26) -> 143 | P26: =IF(C26=0,$L$12,C26) -> 94 | Q26: =IF(D26=0,$L$13,D26) -> 33 | R26: =IF(E26=0,$L$14,E26) -> 146 | S26: =IF(F26=0,$L$15,F26) -> 36.6
A27: 10 | B27: 125 | C27: 70 | D27: 26 | E27: 115 | F27: 31.1 | G27: 0.205 | H27: 41 | I27: 1 | O27: =IF(B27=0,$L$11,B27) -> 125 | P27: =IF(C27=0,$L$12,C27) -> 70 | Q27: =IF(D27=0,$L$13,D27) -> 26 | R27: =IF(E27=0,$L$14,E27) -> 115 | S27: =IF(F27=0,$L$15,F27) -> 31.1
... A769: 1 | B769: 93 | C769: 70 | D769: 31 | E769: 0 | F769: 30.4 | G769: 0.315 | H769: 23 | I769: 0 | O769: =IF(B769=0,$L$11,B769) -> 93 | P769: =IF(C769=0,$L$12,C769) -> 70 | Q769: =IF(D769=0,$L$13,D769) -> 31 | R769: =IF(E769=0,$L$14,E769) -> 30.5 | S769: =IF(F769=0,$L$15,F769) -> 30.4

Sheet TRAINING
A1: Pregnancies | B1: Glucose | C1: BloodPressure | D1: SkinThickness | E1: Insulin | F1: BMI | G1: DiabetesPedigreeFunction | H1: Age | I1: Outcome | J1: PRIOR PROBABILITY | K1: CLASS | L1: PRIOR | M1: MEAN AND STD DEV ATRIBUT PER CLASS | N1: MEAN
A2: 1 | B2: 153 | C2: 82 | D2: 42 | E2: 485 | F2: 40.6 | G2: 0.687 | H2: 23 | I2: 0 | K2: Outcome 0 | L2: =COUNTIF(I2:I616,0)/COUNTA(I2:I616) -> 0.65203252 | O2: Pregnancies | P2: Glucose | Q2: BloodPressure | R2: SkinThickness | S2: Insulin | T2: BMI | U2: DiabetesPedigreeFunction | V2: Age
A3: 8 | B3: 188 | C3: 78 | D3: 23 | E3: 30.5 | F3: 47.9 | G3: 0.137 | H3: 43 | I3: 1 | K3: Outcome 1 | L3: 0.34 | N3: CLASS 0 | O3: =AVERAGEIF($I$2:$I$616,0,A2:A616) -> 3.2219451 | P3: =AVERAGEIF($I$2:$I$616,0,B2:B616) -> 111.25436 | Q3: =AVERAGEIF($I$2:$I$616,0,C2:C616) -> 71.062344 | R3: =AVERAGEIF($I$2:$I$616,0,D2:D616) -> 26.099751 | S3: =AVERAGEIF($I$2:$I$616,0,E2:E616) -> 86.215711 | T3: =AVERAGEIF($I$2:$I$616,0,F2:F616) -> 30.966334 | U3: =AVERAGEIF($I$2:$I$616,0,G2:G616) -> 0.43365835 | V3: =AVERAGEIF($I$2:$I$616,0,H2:H616) -> 31.32419
A4: 7 | B4: 152 | C4: 88 | D4: 44 | E4: 30.5 | F4: 50 | G4: 0.337 | H4: 36 | I4: 1 | N4: CLASS 1 | O4: =AVERAGEIF($I$2:$I$616,1,A2:A616) -> 4.8271028 | P4: =AVERAGEIF($I$2:$I$616,1,B2:B616) -> 143.37383 | Q4: =AVERAGEIF($I$2:$I$616,1,C2:C616) -> 75.383178 | R4: =AVERAGEIF($I$2:$I$616,1,D2:D616) -> 29.738318 | S4: =AVERAGEIF($I$2:$I$616,1,E2:E616) -> 114.10981 | T4: =AVERAGEIF($I$2:$I$616,1,F2:F616) -> 35.311215 | U4: =AVERAGEIF($I$2:$I$616,1,G2:G616) -> 0.55064953 | V4: =AVERAGEIF($I$2:$I$616,1,H2:H616) -> 36.626168
A5: 2 | B5: 99 | C5: 52 | D5: 15 | E5: 94 | F5: 24.6 | G5: 0.637 | H5: 21 | I5: 0
A6: 1 | B6: 109 | C6: 56 | D6: 21 | E6: 135 | F6: 25.2 | G6: 0.833 | H6: 23 | I6: 0 | N6: STD DEVIASI
A7: 2 | B7: 88 | C7: 74 | D7: 19 | E7: 53 | F7: 29 | G7: 0.229 | H7: 22 | I7: 0 | O7: Pregnancies | P7: Glucose | Q7: BloodPressure | R7: SkinThickness | S7: Insulin | T7: BMI | U7: DiabetesPedigreeFunction | V7: Age
A8: 17 | B8: 163 | C8: 72 | D8: 41 | E8: 114 | F8: 40.9 | G8: 0.817 | H8: 47 | I8: 1 | N8: CLASS 0 | O8: {=_xlfn.STDEV.S(_xlfn._xlws.FILTER(A2:A616,$I$2:$I$616=0))} -> 3.0254119 | P8: {=_xlfn.STDEV.S(_xlfn._xlws.FILTER(B2:B616,$I$2:$I$616=0))} -> 24.66141 | Q8: {=_xlfn.STDEV.S(_xlfn._xlws.FILTER(C2:C616,$I$2:$I$616=0))} -> 11.621902 | R8: {=_xlfn.STDEV.S(_xlfn._xlws.FILTER(D2:D616,$I$2:$I$616=0))} -> 8.7800925 | S8: {=_xlfn.STDEV.S(_xlfn._xlws.FILTER(E2:E616,$I$2:$I$616=0))} -> 93.782809 | T8: {=_xlfn.STDEV.S(_xlfn._xlws.FILTER(F2:F616,$I$2:$I$616=0))} -> 6.5286629 | U8: {=_xlfn.STDEV.S(_xlfn._xlws.FILTER(G2:G616,$I$2:$I$616=0))} -> 0.30120525 | V8: {=_xlfn.STDEV.S(_xlfn._xlws.FILTER(H2:H616,$I$2:$I$616=0))} -> 11.870115
A9: 4 | B9: 151 | C9: 90 | D9: 38 | E9: 30.5 | F9: 29.7 | G9: 0.294 | H9: 36 | I9: 0 | N9: CLASS 1 | O9: {=_xlfn.STDEV.S(_xlfn._xlws.FILTER(A2:A616,$I$2:$I$616=1))} -> 3.7118025 | P9: {=_xlfn.STDEV.S(_xlfn._xlws.FILTER(B2:B616,$I$2:$I$616=1))} -> 29.172958 | Q9: {=_xlfn.STDEV.S(_xlfn._xlws.FILTER(C2:C616,$I$2:$I$616=1))} -> 11.265173 | R9: {=_xlfn.STDEV.S(_xlfn._xlws.FILTER(D2:D616,$I$2:$I$616=1))} -> 9.8679892 | S9: {=_xlfn.STDEV.S(_xlfn._xlws.FILTER(E2:E616,$I$2:$I$616=1))} -> 121.14991 | T9: {=_xlfn.STDEV.S(_xlfn._xlws.FILTER(F2:F616,$I$2:$I$616=1))} -> 6.5758104 | U9: {=_xlfn.STDEV.S(_xlfn._xlws.FILTER(G2:G616,$I$2:$I$616=1))} -> 0.36056638 | V9: {=_xlfn.STDEV.S(_xlfn._xlws.FILTER(H2:H616,$I$2:$I$616=1))} -> 10.926148
A10: 7 | B10: 102 | C10: 74 | D10: 40 | E10: 105 | F10: 37.2 | G10: 0.204 | H10: 45 | I10: 0
A11: 0 | B11: 114 | C11: 80 | D11: 34 | E11: 285 | F11: 44.2 | G11: 0.167 | H11: 27 | I11: 0
A12: 2 | B12: 100 | C12: 64 | D12: 23 | E12: 30.5 | F12: 29.7 | G12: 0.368 | H12: 21 | I12: 0
A13: 0 | B13: 131 | C13: 88 | D13: 23 | E13: 30.5 | F13: 31.6 | G13: 0.743 | H13: 32 | I13: 1
A14: 6 | B14: 104 | C14: 74 | D14: 18 | E14: 156 | F14: 29.9 | G14: 0.722 | H14: 41 | I14: 1
A15: 3 | B15: 148 | C15: 66 | D15: 25 | E15: 30.5 | F15: 32.5 | G15: 0.256 | H15: 22 | I15: 0
A16: 4 | B16: 120 | C16: 68 | D16: 23 | E16: 30.5 | F16: 29.6 | G16: 0.709 | H16: 34 | I16: 0
A17: 4 | B17: 110 | C17: 66 | D17: 23 | E17: 30.5 | F17: 31.9 | G17: 0.471 | H17: 29 | I17: 0
A18: 3 | B18: 111 | C18: 90 | D18: 12 | E18: 78 | F18: 28.4 | G18: 0.495 | H18: 29 | I18: 0
A19: 6 | B19: 102 | C19: 82 | D19: 23 | E19: 30.5 | F19: 30.8 | G19: 0.18 | H19: 36 | I19: 1
A20: 6 | B20: 134 | C20: 70 | D20: 23 | E20: 130 | F20: 35.4 | G20: 0.542 | H20: 29 | I20: 1
A21: 2 | B21: 87 | C21: 72 | D21: 23 | E21: 30.5 | F21: 28.9 | G21: 0.773 | H21: 25 | I21: 0
... A616: 1 | B616: 93 | C616: 70 | D616: 31 | E616: 30.5 | F616: 30.4 | G616: 0.315 | H616: 23 | I616: 0

Sheet TESTING
A1: Pregnancies | B1: Glucose | C1: BloodPressure | D1: SkinThickness | E1: Insulin | F1: BMI | G1: DiabetesPedigreeFunction | H1: Age | I1: Outcome | K1: PREG_0 | L1: PREG_1 | M1: Glucose_0 | N1: Glucose_1 | O1: BloodPressure_0 | P1: BloodPressure_1 | Q1: SkinThickness_0 | R1: SkinThickness_1 | S1: Insulin_0 | T1: Insulin_1 | U1: BMI_0 | V1: BMI_1 | W1: DiabetesP_0 | X1: DiabetesP_1 | Y1: Age_0 | Z1: Age_1 | AA1: Total_0 | AB1: Total_1 | AC1: Prediksi | AD1: Hasil | AE1: Akurasi | AF1: EVALUASI MODEL CONFUSION MATRIX | AG1: CM | AH1: TOTAL
A2: 6 | B2: 148 | C2: 72 | D2: 35 | E2: 30.5 | F2: 33.6 | G2: 0.627 | H2: 50 | I2: 1 | K2: =(1/(SQRT(2*PI())*TRAINING!$O$8))*EXP(-((A2-TRAINING!$O$3)^2)/(2*(TRAINING!$O$8^2))) -> 0.08650368 | L2: =(1/(SQRT(2*PI())*TRAINING!$O$9))*EXP(-((A2-TRAINING!$O$4)^2)/(2*(TRAINING!$O$9^2))) -> 0.1022452 | M2: =(1/(SQRT(2*PI())*TRAINING!$P$8))*EXP(-((B2-TRAINING!$P$3)^2)/(2*(TRAINING!$P$8^2))) -> 0.0053308938 | N2: =(1/(SQRT(2*PI())*TRAINING!$P$9))*EXP(-((B2-TRAINING!$P$4)^2)/(2*(TRAINING!$P$9^2))) -> 0.013504206 | O2: =(1/(SQRT(2*PI())*TRAINING!$Q$8))*EXP(-((C2-TRAINING!$Q$3)^2)/(2*(TRAINING!$Q$8^2))) -> 0.034215224 | P2: =(1/(SQRT(2*PI())*TRAINING!$Q$9))*EXP(-((C2-TRAINING!$Q$4)^2)/(2*(TRAINING!$Q$9^2))) -> 0.033852207 | Q2: =(1/(SQRT(2*PI())*TRAINING!$R$8))*EXP(-((D2-TRAINING!$R$3)^2)/(2*(TRAINING!$R$8^2))) -> 0.027181892 | R2: =(1/(SQRT(2*PI())*TRAINING!$R$9))*EXP(-((D2-TRAINING!$R$4)^2)/(2*(TRAINING!$R$9^2))) -> 0.035070689 | S2: =(1/(SQRT(2*PI())*TRAINING!$S$8))*EXP(-((E2-TRAINING!$S$3)^2)/(2*(TRAINING!$S$8^2))) -> 0.0035657055 | T2: =(1/(SQRT(2*PI())*TRAINING!$S$9))*EXP(-((E2-TRAINING!$S$4)^2)/(2*(TRAINING!$S$9^2))) -> 0.0025951511 | U2: =(1/(SQRT(2*PI())*TRAINING!$T$8))*EXP(-((F2-TRAINING!$T$3)^2)/(2*(TRAINING!$T$8^2))) -> 0.056331203 | V2: =(1/(SQRT(2*PI())*TRAINING!$T$9))*EXP(-((F2-TRAINING!$T$4)^2)/(2*(TRAINING!$T$9^2))) -> 0.058648349 | W2: =(1/(SQRT(2*PI())*TRAINING!$U$8))*EXP(-((G2-TRAINING!$U$3)^2)/(2*(TRAINING!$U$8^2))) -> 1.0778963 | X2: =(1/(SQRT(2*PI())*TRAINING!$U$9))*EXP(-((G2-TRAINING!$U$4)^2)/(2*(TRAINING!$U$9^2))) -> 1.0819028 | Y2: =(1/(SQRT(2*PI())*TRAINING!$V$8))*EXP(-((H2-TRAINING!$V$3)^2)/(2*(TRAINING!$V$8^2))) -> 0.0097481977 | Z2: =(1/(SQRT(2*PI())*TRAINING!$V$9))*EXP(-((H2-TRAINING!$V$4)^2)/(2*(TRAINING!$V$9^2))) -> 0.017262639 | AA2: =PRODUCT(K2,M2,O2,Q2,S2,U2,W2,Y2)*TRAINING!$L$2 -> 5.9019939e-13 | AB2: =PRODUCT(L2,N2,P2,R2,T2,V2,X2,Z2)*TRAINING!$L$3 -> 1.5842951e-12 | AC2: =IF(AB2>AA2,1,0) -> 1 | AD2: =IF(I2=AC2,1,0) -> 1 | AE2: =AVERAGE(AD2:AD154)*100 -> 75.163399 | AG2: =IF(AND(AC2=1,I2=1),"TP",IF(AND(AC2=0,I2=0),"TN",IF(AND(AC2=1,I2=0),"FP","FN"))) -> TP | AH2: TP | AI2: 31
A3: 1 | B3: 85 | C3: 66 | D3: 29 | E3: 30.5 | F3: 26.6 | G3: 0.351 | H3: 31 | I3: 0 | K3: =(1/(SQRT(2*PI())*TRAINING!$O$8))*EXP(-((A3-TRAINING!$O$3)^2)/(2*(TRAINING!$O$8^2))) -> 0.10069315 | L3: =(1/(SQRT(2*PI())*TRAINING!$O$9))*EXP(-((A3-TRAINING!$O$4)^2)/(2*(TRAINING!$O$9^2))) -> 0.0631652 | M3: =(1/(SQRT(2*PI())*TRAINING!$P$8))*EXP(-((B3-TRAINING!$P$3)^2)/(2*(TRAINING!$P$8^2))) -> 0.0091788136 | N3: =(1/(SQRT(2*PI())*TRAINING!$P$9))*EXP(-((B3-TRAINING!$P$4)^2)/(2*(TRAINING!$P$9^2))) -> 0.0018471802 | O3: =(1/(SQRT(2*PI())*TRAINING!$Q$8))*EXP(-((C3-TRAINING!$Q$3)^2)/(2*(TRAINING!$Q$8^2))) -> 0.031219956 | P3: =(1/(SQRT(2*PI())*TRAINING!$Q$9))*EXP(-((C3-TRAINING!$Q$4)^2)/(2*(TRAINING!$Q$9^2))) -> 0.02503335 | Q3: =(1/(SQRT(2*PI())*TRAINING!$R$8))*EXP(-((D3-TRAINING!$R$3)^2)/(2*(TRAINING!$R$8^2))) -> 0.043024676 | R3: =(1/(SQRT(2*PI())*TRAINING!$R$9))*EXP(-((D3-TRAINING!$R$4)^2)/(2*(TRAINING!$R$9^2))) -> 0.040314922 | S3: =(1/(SQRT(2*PI())*TRAINING!$S$8))*EXP(-((E3-TRAINING!$S$3)^2)/(2*(TRAINING!$S$8^2))) -> 0.0035657055 | T3: =(1/(SQRT(2*PI())*TRAINING!$S$9))*EXP(-((E3-TRAINING!$S$4)^2)/(2*(TRAINING!$S$9^2))) -> 0.0025951511 | U3: =(1/(SQRT(2*PI())*TRAINING!$T$8))*EXP(-((F3-TRAINING!$T$3)^2)/(2*(TRAINING!$T$8^2))) -> 0.048860608 | V3: =(1/(SQRT(2*PI())*TRAINING!$T$9))*EXP(-((F3-TRAINING!$T$4)^2)/(2*(TRAINING!$T$9^2))) -> 0.025228032 | W3: =(1/(SQRT(2*PI())*TRAINING!$U$8))*EXP(-((G3-TRAINING!$U$3)^2)/(2*(TRAINING!$U$8^2))) -> 1.2755407 | X3: =(1/(SQRT(2*PI())*TRAINING!$U$9))*EXP(-((G3-TRAINING!$U$4)^2)/(2*(TRAINING!$U$9^2))) -> 0.94917964 | Y3: =(1/(SQRT(2*PI())*TRAINING!$V$8))*EXP(-((H3-TRAINING!$V$3)^2)/(2*(TRAINING!$V$8^2))) -> 0.033596432 | Z3: =(1/(SQRT(2*PI())*TRAINING!$V$9))*EXP(-((H3-TRAINING!$V$4)^2)/(2*(TRAINING!$V$9^2))) -> 0.031979114 | AA3: =PRODUCT(K3,M3,O3,Q3,S3,U3,W3,Y3)*TRAINING!$L$2 -> 6.0436242e-12 | AB3: =PRODUCT(L3,N3,P3,R3,T3,V3,X3,Z3)*TRAINING!$L$3 -> 7.9563104e-14 | AC3: =IF(AB3>AA3,1,0) -> 0 | AD3: =IF(I3=AC3,1,0) -> 1 | AG3: =IF(AND(AC3=1,I3=1),"TP",IF(AND(AC3=0,I3=0),"TN",IF(AND(AC3=1,I3=0),"FP","FN"))) -> TN | AH3: TN | AI3: =COUNTIFS($I$2:$I$154,0,$AC$2:$AC$154,0) -> 84
A4: 8 | B4: 183 | C4: 64 | D4: 23 | E4: 30.5 | F4: 23.3 | G4: 0.672 | H4: 32 | I4: 1 | K4: =(1/(SQRT(2*PI())*TRAINING!$O$8))*EXP(-((A4-TRAINING!$O$3)^2)/(2*(TRAINING!$O$8^2))) -> 0.037889114 | L4: =(1/(SQRT(2*PI())*TRAINING!$O$9))*EXP(-((A4-TRAINING!$O$4)^2)/(2*(TRAINING!$O$9^2))) -> 0.074585526 | M4: =(1/(SQRT(2*PI())*TRAINING!$P$8))*EXP(-((B4-TRAINING!$P$3)^2)/(2*(TRAINING!$P$8^2))) -> 0.0002349874 | N4: =(1/(SQRT(2*PI())*TRAINING!$P$9))*EXP(-((B4-TRAINING!$P$4)^2)/(2*(TRAINING!$P$9^2))) -> 0.0054360897 | O4: =(1/(SQRT(2*PI())*TRAINING!$Q$8))*EXP(-((C4-TRAINING!$Q$3)^2)/(2*(TRAINING!$Q$8^2))) -> 0.028539544 | P4: =(1/(SQRT(2*PI())*TRAINING!$Q$9))*EXP(-((C4-TRAINING!$Q$4)^2)/(2*(TRAINING!$Q$9^2))) -> 0.021254546 | Q4: =(1/(SQRT(2*PI())*TRAINING!$R$8))*EXP(-((D4-TRAINING!$R$3)^2)/(2*(TRAINING!$R$8^2))) -> 0.042691938 | R4: =(1/(SQRT(2*PI())*TRAINING!$R$9))*EXP(-((D4-TRAINING!$R$4)^2)/(2*(TRAINING!$R$9^2))) -> 0.032020658 | S4: =(1/(SQRT(2*PI())*TRAINING!$S$8))*EXP(-((E4-TRAINING!$S$3)^2)/(2*(TRAINING!$S$8^2))) -> 0.0035657055 | T4: =(1/(SQRT(2*PI())*TRAINING!$S$9))*EXP(-((E4-TRAINING!$S$4)^2)/(2*(TRAINING!$S$9^2))) -> 0.0025951511 | U4: =(1/(SQRT(2*PI())*TRAINING!$T$8))*EXP(-((F4-TRAINING!$T$3)^2)/(2*(TRAINING!$T$8^2))) -> 0.030666589 | V4: =(1/(SQRT(2*PI())*TRAINING!$T$9))*EXP(-((F4-TRAINING!$T$4)^2)/(2*(TRAINING!$T$9^2))) -> 0.011441301 | W4: =(1/(SQRT(2*PI())*TRAINING!$U$8))*EXP(-((G4-TRAINING!$U$3)^2)/(2*(TRAINING!$U$8^2))) -> 0.96846049 | X4: =(1/(SQRT(2*PI())*TRAINING!$U$9))*EXP(-((G4-TRAINING!$U$4)^2)/(2*(TRAINING!$U$9^2))) -> 1.0455112 | Y4: =(1/(SQRT(2*PI())*TRAINING!$V$8))*EXP(-((H4-TRAINING!$V$3)^2)/(2*(TRAINING!$V$8^2))) -> 0.033554537 | Z4: =(1/(SQRT(2*PI())*TRAINING!$V$9))*EXP(-((H4-TRAINING!$V$4)^2)/(2*(TRAINING!$V$9^2))) -> 0.033382195 | AA4: =PRODUCT(K4,M4,O4,Q4,S4,U4,W4,Y4)*TRAINING!$L$2 -> 2.5134213e-14 | AB4: =PRODUCT(L4,N4,P4,R4,T4,V4,X4,Z4)*TRAINING!$L$3 -> 9.7226312e-14 | AC4: =IF(AB4>AA4,1,0) -> 1 | AD4: =IF(I4=AC4,1,0) -> 1 | AG4: =IF(AND(AC4=1,I4=1),"TP",IF(AND(AC4=0,I4=0),"TN",IF(AND(AC4=1,I4=0),"FP","FN"))) -> TP | AH4: FP | AI4: =COUNTIFS($I$2:$I$154,0,$AC$2:$AC$154,1) -> 15
A5: 1 | B5: 89 | C5: 66 | D5: 23 | E5: 94 | F5: 28.1 | G5: 0.167 | H5: 21 | I5: 0 | K5: =(1/(SQRT(2*PI())*TRAINING!$O$8))*EXP(-((A5-TRAINING!$O$3)^2)/(2*(TRAINING!$O$8^2))) -> 0.10069315 | L5: =(1/(SQRT(2*PI())*TRAINING!$O$9))*EXP(-((A5-TRAINING!$O$4)^2)/(2*(TRAINING!$O$9^2))) -> 0.0631652 | M5: =(1/(SQRT(2*PI())*TRAINING!$P$8))*EXP(-((B5-TRAINING!$P$3)^2)/(2*(TRAINING!$P$8^2))) -> 0.010766264 | N5: =(1/(SQRT(2*PI())*TRAINING!$P$9))*EXP(-((B5-TRAINING!$P$4)^2)/(2*(TRAINING!$P$9^2))) -> 0.0024075702 | O5: =(1/(SQRT(2*PI())*TRAINING!$Q$8))*EXP(-((C5-TRAINING!$Q$3)^2)/(2*(TRAINING!$Q$8^2))) -> 0.031219956 | P5: =(1/(SQRT(2*PI())*TRAINING!$Q$9))*EXP(-((C5-TRAINING!$Q$4)^2)/(2*(TRAINING!$Q$9^2))) -> 0.02503335 | Q5: =(1/(SQRT(2*PI())*TRAINING!$R$8))*EXP(-((D5-TRAINING!$R$3)^2)/(2*(TRAINING!$R$8^2))) -> 0.042691938 | R5: =(1/(SQRT(2*PI())*TRAINING!$R$9))*EXP(-((D5-TRAINING!$R$4)^2)/(2*(TRAINING!$R$9^2))) -> 0.032020658 | S5: =(1/(SQRT(2*PI())*TRAINING!$S$8))*EXP(-((E5-TRAINING!$S$3)^2)/(2*(TRAINING!$S$8^2))) -> 0.0042392671 | T5: =(1/(SQRT(2*PI())*TRAINING!$S$9))*EXP(-((E5-TRAINING!$S$4)^2)/(2*(TRAINING!$S$9^2))) -> 0.0032479093 | U5: =(1/(SQRT(2*PI())*TRAINING!$T$8))*EXP(-((F5-TRAINING!$T$3)^2)/(2*(TRAINING!$T$8^2))) -> 0.055491908 | V5: =(1/(SQRT(2*PI())*TRAINING!$T$9))*EXP(-((F5-TRAINING!$T$4)^2)/(2*(TRAINING!$T$9^2))) -> 0.033252266 | W5: =(1/(SQRT(2*PI())*TRAINING!$U$8))*EXP(-((G5-TRAINING!$U$3)^2)/(2*(TRAINING!$U$8^2))) -> 0.89506657 | X5: =(1/(SQRT(2*PI())*TRAINING!$U$9))*EXP(-((G5-TRAINING!$U$4)^2)/(2*(TRAINING!$U$9^2))) -> 0.62818052 | Y5: =(1/(SQRT(2*PI())*TRAINING!$V$8))*EXP(-((H5-TRAINING!$V$3)^2)/(2*(TRAINING!$V$8^2))) -> 0.023024268 | Z5: =(1/(SQRT(2*PI())*TRAINING!$V$9))*EXP(-((H5-TRAINING!$V$4)^2)/(2*(TRAINING!$V$9^2))) -> 0.013130995 | AA5: =PRODUCT(K5,M5,O5,Q5,S5,U5,W5,Y5)*TRAINING!$L$2 -> 4.567452e-12 | AB5: =PRODUCT(L5,N5,P5,R5,T5,V5,X5,Z5)*TRAINING!$L$3 -> 3.6922593e-14 | AC5: =IF(AB5>AA5,1,0) -> 0 | AD5: =IF(I5=AC5,1,0) -> 1 | AG5: =IF(AND(AC5=1,I5=1),"TP",IF(AND(AC5=0,I5=0),"TN",IF(AND(AC5=1,I5=0),"FP","FN"))) -> TN | AH5: FN | AI5: 23
A6: 0 | B6: 137 | C6: 40 | D6: 35 | E6: 168 | F6: 43.1 | G6: 2.288 | H6: 33 | I6: 1 | K6: =(1/(SQRT(2*PI())*TRAINING!$O$8))*EXP(-((A6-TRAINING!$O$3)^2)/(2*(TRAINING!$O$8^2))) -> 0.074791087 | L6: =(1/(SQRT(2*PI())*TRAINING!$O$9))*EXP(-((A6-TRAINING!$O$4)^2)/(2*(TRAINING!$O$9^2))) -> 0.046140116 | M6: =(1/(SQRT(2*PI())*TRAINING!$P$8))*EXP(-((B6-TRAINING!$P$3)^2)/(2*(TRAINING!$P$8^2))) -> 0.0093806228 | N6: =(1/(SQRT(2*PI())*TRAINING!$P$9))*EXP(-((B6-TRAINING!$P$4)^2)/(2*(TRAINING!$P$9^2))) -> 0.013352543 | O6: =(1/(SQRT(2*PI())*TRAINING!$Q$8))*EXP(-((C6-TRAINING!$Q$3)^2)/(2*(TRAINING!$Q$8^2))) -> 0.00096478568 | P6: =(1/(SQRT(2*PI())*TRAINING!$Q$9))*EXP(-((C6-TRAINING!$Q$4)^2)/(2*(TRAINING!$Q$9^2))) -> 0.00025521838 | Q6: =(1/(SQRT(2*PI())*TRAINING!$R$8))*EXP(-((D6-TRAINING!$R$3)^2)/(2*(TRAINING!$R$8^2))) -> 0.027181892 | R6: =(1/(SQRT(2*PI())*TRAINING!$R$9))*EXP(-((D6-TRAINING!$R$4)^2)/(2*(TRAINING!$R$9^2))) -> 0.035070689 | S6: =(1/(SQRT(2*PI())*TRAINING!$S$8))*EXP(-((E6-TRAINING!$S$3)^2)/(2*(TRAINING!$S$8^2))) -> 0.002908363 | T6: =(1/(SQRT(2*PI())*TRAINING!$S$9))*EXP(-((E6-TRAINING!$S$4)^2)/(2*(TRAINING!$S$9^2))) -> 0.0029827765 | U6: =(1/(SQRT(2*PI())*TRAINING!$T$8))*EXP(-((F6-TRAINING!$T$3)^2)/(2*(TRAINING!$T$8^2))) -> 0.010865166 | V6: =(1/(SQRT(2*PI())*TRAINING!$T$9))*EXP(-((F6-TRAINING!$T$4)^2)/(2*(TRAINING!$T$9^2))) -> 0.030082574 | W6: =(1/(SQRT(2*PI())*TRAINING!$U$8))*EXP(-((G6-TRAINING!$U$3)^2)/(2*(TRAINING!$U$8^2))) -> 7.7961196e-09 | X6: =(1/(SQRT(2*PI())*TRAINING!$U$9))*EXP(-((G6-TRAINING!$U$4)^2)/(2*(TRAINING!$U$9^2))) -> 1.0056272e-05 | Y6: =(1/(SQRT(2*PI())*TRAINING!$V$8))*EXP(-((H6-TRAINING!$V$3)^2)/(2*(TRAINING!$V$8^2))) -> 0.033275689 | Z6: =(1/(SQRT(2*PI())*TRAINING!$V$9))*EXP(-((H6-TRAINING!$V$4)^2)/(2*(TRAINING!$V$9^2))) -> 0.034556158 | AA6: =PRODUCT(K6,M6,O6,Q6,S6,U6,W6,Y6)*TRAINING!$L$2 -> 9.83449e-23 | AB6: =PRODUCT(L6,N6,P6,R6,T6,V6,X6,Z6)*TRAINING!$L$3 -> 5.8462317e-20 | AC6: =IF(AB6>AA6,1,0) -> 1 | AD6: =IF(I6=AC6,1,0) -> 1 | AG6: =IF(AND(AC6=1,I6=1),"TP",IF(AND(AC6=0,I6=0),"TN",IF(AND(AC6=1,I6=0),"FP","FN"))) -> TP | AI6: =AI2+AI3+AI4+AI5 -> 153
A7: 5 | B7: 116 | C7: 74 | D7: 23 | E7: 30.5 | F7: 25.6 | G7: 0.201 | H7: 30 | I7: 0 | K7: =(1/(SQRT(2*PI())*TRAINING!$O$8))*EXP(-((A7-TRAINING!$O$3)^2)/(2*(TRAINING!$O$8^2))) -> 0.11094892 | L7: =(1/(SQRT(2*PI())*TRAINING!$O$9))*EXP(-((A7-TRAINING!$O$4)^2)/(2*(TRAINING!$O$9^2))) -> 0.10736286 | M7: =(1/(SQRT(2*PI())*TRAINING!$P$8))*EXP(-((B7-TRAINING!$P$3)^2)/(2*(TRAINING!$P$8^2))) -> 0.015880026 | N7: =(1/(SQRT(2*PI())*TRAINING!$P$9))*EXP(-((B7-TRAINING!$P$4)^2)/(2*(TRAINING!$P$9^2))) -> 0.008805213 | O7: =(1/(SQRT(2*PI())*TRAINING!$Q$8))*EXP(-((C7-TRAINING!$Q$3)^2)/(2*(TRAINING!$Q$8^2))) -> 0.03324749 | P7: =(1/(SQRT(2*PI())*TRAINING!$Q$9))*EXP(-((C7-TRAINING!$Q$4)^2)/(2*(TRAINING!$Q$9^2))) -> 0.03514783 | Q7: =(1/(SQRT(2*PI())*TRAINING!$R$8))*EXP(-((D7-TRAINING!$R$3)^2)/(2*(TRAINING!$R$8^2))) -> 0.042691938 | R7: =(1/(SQRT(2*PI())*TRAINING!$R$9))*EXP(-((D7-TRAINING!$R$4)^2)/(2*(TRAINING!$R$9^2))) -> 0.032020658 | S7: =(1/(SQRT(2*PI())*TRAINING!$S$8))*EXP(-((E7-TRAINING!$S$3)^2)/(2*(TRAINING!$S$8^2))) -> 0.0035657055 | T7: =(1/(SQRT(2*PI())*TRAINING!$S$9))*EXP(-((E7-TRAINING!$S$4)^2)/(2*(TRAINING!$S$9^2))) -> 0.0025951511 | U7: =(1/(SQRT(2*PI())*TRAINING!$T$8))*EXP(-((F7-TRAINING!$T$3)^2)/(2*(TRAINING!$T$8^2))) -> 0.043588839 | V7: =(1/(SQRT(2*PI())*TRAINING!$T$9))*EXP(-((F7-TRAINING!$T$4)^2)/(2*(TRAINING!$T$9^2))) -> 0.020387801 | W7: =(1/(SQRT(2*PI())*TRAINING!$U$8))*EXP(-((G7-TRAINING!$U$3)^2)/(2*(TRAINING!$U$8^2))) -> 0.98285362 | X7: =(1/(SQRT(2*PI())*TRAINING!$U$9))*EXP(-((G7-TRAINING!$U$4)^2)/(2*(TRAINING!$U$9^2))) -> 0.69139725 | Y7: =(1/(SQRT(2*PI())*TRAINING!$V$8))*EXP(-((H7-TRAINING!$V$3)^2)/(2*(TRAINING!$V$8^2))) -> 0.033400484 | Z7: =(1/(SQRT(2*PI())*TRAINING!$V$9))*EXP(-((H7-TRAINING!$V$4)^2)/(2*(TRAINING!$V$9^2))) -> 0.030379462 | AA7: =PRODUCT(K7,M7,O7,Q7,S7,U7,W7,Y7)*TRAINING!$L$2 -> 8.3197572e-12 | AB7: =PRODUCT(L7,N7,P7,R7,T7,V7,X7,Z7)*TRAINING!$L$3 -> 4.0201511e-13 | AC7: =IF(AB7>AA7,1,0) -> 0 | AD7: =IF(I7=AC7,1,0) -> 1 | AG7: =IF(AND(AC7=1,I7=1),"TP",IF(AND(AC7=0,I7=0),"TN",IF(AND(AC7=1,I7=0),"FP","FN"))) -> TN | AH7: HASIL CM
A8: 3 | B8: 78 | C8: 50 | D8: 32 | E8: 88 | F8: 31 | G8: 0.248 | H8: 26 | I8: 1 | K8: =(1/(SQRT(2*PI())*TRAINING!$O$8))*EXP(-((A8-TRAINING!$O$3)^2)/(2*(TRAINING!$O$8^2))) -> 0.13150944 | L8: =(1/(SQRT(2*PI())*TRAINING!$O$9))*EXP(-((A8-TRAINING!$O$4)^2)/(2*(TRAINING!$O$9^2))) -> 0.095216033 | M8: =(1/(SQRT(2*PI())*TRAINING!$P$8))*EXP(-((B8-TRAINING!$P$3)^2)/(2*(TRAINING!$P$8^2))) -> 0.0065171395 | N8: =(1/(SQRT(2*PI())*TRAINING!$P$9))*EXP(-((B8-TRAINING!$P$4)^2)/(2*(TRAINING!$P$9^2))) -> 0.0011104292 | O8: =(1/(SQRT(2*PI())*TRAINING!$Q$8))*EXP(-((C8-TRAINING!$Q$3)^2)/(2*(TRAINING!$Q$8^2))) -> 0.0066439998 | P8: =(1/(SQRT(2*PI())*TRAINING!$Q$9))*EXP(-((C8-TRAINING!$Q$4)^2)/(2*(TRAINING!$Q$9^2))) -> 0.0027970012 | Q8: =(1/(SQRT(2*PI())*TRAINING!$R$8))*EXP(-((D8-TRAINING!$R$3)^2)/(2*(TRAINING!$R$8^2))) -> 0.036253492 | R8: =(1/(SQRT(2*PI())*TRAINING!$R$9))*EXP(-((D8-TRAINING!$R$4)^2)/(2*(TRAINING!$R$9^2))) -> 0.039379908 | S8: =(1/(SQRT(2*PI())*TRAINING!$S$8))*EXP(-((E8-TRAINING!$S$3)^2)/(2*(TRAINING!$S$8^2))) -> 0.0042531258 | T8: =(1/(SQRT(2*PI())*TRAINING!$S$9))*EXP(-((E8-TRAINING!$S$4)^2)/(2*(TRAINING!$S$9^2))) -> 0.0032173702 | U8: =(1/(SQRT(2*PI())*TRAINING!$T$8))*EXP(-((F8-TRAINING!$T$3)^2)/(2*(TRAINING!$T$8^2))) -> 0.061105464 | V8: =(1/(SQRT(2*PI())*TRAINING!$T$9))*EXP(-((F8-TRAINING!$T$4)^2)/(2*(TRAINING!$T$9^2))) -> 0.048935442 | W8: =(1/(SQRT(2*PI())*TRAINING!$U$8))*EXP(-((G8-TRAINING!$U$3)^2)/(2*(TRAINING!$U$8^2))) -> 1.0953344 | X8: =(1/(SQRT(2*PI())*TRAINING!$U$9))*EXP(-((G8-TRAINING!$U$4)^2)/(2*(TRAINING!$U$9^2))) -> 0.7779193 | Y8: =(1/(SQRT(2*PI())*TRAINING!$V$8))*EXP(-((H8-TRAINING!$V$3)^2)/(2*(TRAINING!$V$8^2))) -> 0.030392624 | Z8: =(1/(SQRT(2*PI())*TRAINING!$V$9))*EXP(-((H8-TRAINING!$V$4)^2)/(2*(TRAINING!$V$9^2))) -> 0.022753893 | AA8: =PRODUCT(K8,M8,O8,Q8,S8,U8,W8,Y8)*TRAINING!$L$2 -> 1.1645707e-12 | AB8: =PRODUCT(L8,N8,P8,R8,T8,V8,X8,Z8)*TRAINING!$L$3 -> 1.1034738e-14 | AC8: =IF(AB8>AA8,1,0) -> 0 | AD8: =IF(I8=AC8,1,0) -> 0 | AG8: =IF(AND(AC8=1,I8=1),"TP",IF(AND(AC8=0,I8=0),"TN",IF(AND(AC8=1,I8=0),"FP","FN"))) -> FN | AH8: ACCURACY | AI8: =((AI2+AI3)/(AI2+AI3+AI4+AI5)) -> 0.75163399
A9: 10 | B9: 115 | C9: 72 | D9: 23 | E9: 30.5 | F9: 35.3 | G9: 0.134 | H9: 29 | I9: 0 | K9: =(1/(SQRT(2*PI())*TRAINING!$O$8))*EXP(-((A9-TRAINING!$O$3)^2)/(2*(TRAINING!$O$8^2))) -> 0.010720214 | L9: =(1/(SQRT(2*PI())*TRAINING!$O$9))*EXP(-((A9-TRAINING!$O$4)^2)/(2*(TRAINING!$O$9^2))) -> 0.040698455 | M9: =(1/(SQRT(2*PI())*TRAINING!$P$8))*EXP(-((B9-TRAINING!$P$3)^2)/(2*(TRAINING!$P$8^2))) -> 0.01599127 | N9: =(1/(SQRT(2*PI())*TRAINING!$P$9))*EXP(-((B9-TRAINING!$P$4)^2)/(2*(TRAINING!$P$9^2))) -> 0.0085214975 | O9: =(1/(SQRT(2*PI())*TRAINING!$Q$8))*EXP(-((C9-TRAINING!$Q$3)^2)/(2*(TRAINING!$Q$8^2))) -> 0.034215224 | P9: =(1/(SQRT(2*PI())*TRAINING!$Q$9))*EXP(-((C9-TRAINING!$Q$4)^2)/(2*(TRAINING!$Q$9^2))) -> 0.033852207 | Q9: =(1/(SQRT(2*PI())*TRAINING!$R$8))*EXP(-((D9-TRAINING!$R$3)^2)/(2*(TRAINING!$R$8^2))) -> 0.042691938 | R9: =(1/(SQRT(2*PI())*TRAINING!$R$9))*EXP(-((D9-TRAINING!$R$4)^2)/(2*(TRAINING!$R$9^2))) -> 0.032020658 | S9: =(1/(SQRT(2*PI())*TRAINING!$S$8))*EXP(-((E9-TRAINING!$S$3)^2)/(2*(TRAINING!$S$8^2))) -> 0.0035657055 | T9: =(1/(SQRT(2*PI())*TRAINING!$S$9))*EXP(-((E9-TRAINING!$S$4)^2)/(2*(TRAINING!$S$9^2))) -> 0.0025951511 | U9: =(1/(SQRT(2*PI())*TRAINING!$T$8))*EXP(-((F9-TRAINING!$T$3)^2)/(2*(TRAINING!$T$8^2))) -> 0.049023782 | V9: =(1/(SQRT(2*PI())*TRAINING!$T$9))*EXP(-((F9-TRAINING!$T$4)^2)/(2*(TRAINING!$T$9^2))) -> 0.060668066 | W9: =(1/(SQRT(2*PI())*TRAINING!$U$8))*EXP(-((G9-TRAINING!$U$3)^2)/(2*(TRAINING!$U$8^2))) -> 0.80746733 | X9: =(1/(SQRT(2*PI())*TRAINING!$U$9))*EXP(-((G9-TRAINING!$U$4)^2)/(2*(TRAINING!$U$9^2))) -> 0.56750951 | Y9: =(1/(SQRT(2*PI())*TRAINING!$V$8))*EXP(-((H9-TRAINING!$V$3)^2)/(2*(TRAINING!$V$8^2))) -> 0.032970844 | Z9: =(1/(SQRT(2*PI())*TRAINING!$V$9))*EXP(-((H9-TRAINING!$V$4)^2)/(2*(TRAINING!$V$9^2))) -> 0.02861909 | AA9: =PRODUCT(K9,M9,O9,Q9,S9,U9,W9,Y9)*TRAINING!$L$2 -> 7.5985067e-13 | AB9: =PRODUCT(L9,N9,P9,R9,T9,V9,X9,Z9)*TRAINING!$L$3 -> 3.2684495e-13 | AC9: =IF(AB9>AA9,1,0) -> 0 | AD9: =IF(I9=AC9,1,0) -> 1 | AG9: =IF(AND(AC9=1,I9=1),"TP",IF(AND(AC9=0,I9=0),"TN",IF(AND(AC9=1,I9=0),"FP","FN"))) -> TN | AH9: PRECISSION | AI9: =(AI2/(AI2+AI4)) -> 0.67391304
A10: 2 | B10: 197 | C10: 70 | D10: 45 | E10: 543 | F10: 30.5 | G10: 0.158 | H10: 53 | I10: 1 | K10: =(1/(SQRT(2*PI())*TRAINING!$O$8))*EXP(-((A10-TRAINING!$O$3)^2)/(2*(TRAINING!$O$8^2))) -> 0.12153526 | L10: =(1/(SQRT(2*PI())*TRAINING!$O$9))*EXP(-((A10-TRAINING!$O$4)^2)/(2*(TRAINING!$O$9^2))) -> 0.080418323 | M10: =(1/(SQRT(2*PI())*TRAINING!$P$8))*EXP(-((B10-TRAINING!$P$3)^2)/(2*(TRAINING!$P$8^2))) -> 3.8354121e-05 | N10: =(1/(SQRT(2*PI())*TRAINING!$P$9))*EXP(-((B10-TRAINING!$P$4)^2)/(2*(TRAINING!$P$9^2))) -> 0.0025245363 | O10: =(1/(SQRT(2*PI())*TRAINING!$Q$8))*EXP(-((C10-TRAINING!$Q$3)^2)/(2*(TRAINING!$Q$8^2))) -> 0.034183653 | P10: =(1/(SQRT(2*PI())*TRAINING!$Q$9))*EXP(-((C10-TRAINING!$Q$4)^2)/(2*(TRAINING!$Q$9^2))) -> 0.031592685 | Q10: =(1/(SQRT(2*PI())*TRAINING!$R$8))*EXP(-((D10-TRAINING!$R$3)^2)/(2*(TRAINING!$R$8^2))) -> 0.004479144 | R10: =(1/(SQRT(2*PI())*TRAINING!$R$9))*EXP(-((D10-TRAINING!$R$4)^2)/(2*(TRAINING!$R$9^2))) -> 0.012225921 | S10: =(1/(SQRT(2*PI())*TRAINING!$S$8))*EXP(-((E10-TRAINING!$S$3)^2)/(2*(TRAINING!$S$8^2))) -> 3.0014344e-08 | T10: =(1/(SQRT(2*PI())*TRAINING!$S$9))*EXP(-((E10-TRAINING!$S$4)^2)/(2*(TRAINING!$S$9^2))) -> 6.2537018e-06 | U10: =(1/(SQRT(2*PI())*TRAINING!$T$8))*EXP(-((F10-TRAINING!$T$3)^2)/(2*(TRAINING!$T$8^2))) -> 0.060950591 | V10: =(1/(SQRT(2*PI())*TRAINING!$T$9))*EXP(-((F10-TRAINING!$T$4)^2)/(2*(TRAINING!$T$9^2))) -> 0.046421396 | W10: =(1/(SQRT(2*PI())*TRAINING!$U$8))*EXP(-((G10-TRAINING!$U$3)^2)/(2*(TRAINING!$U$8^2))) -> 0.87131088 | X10: =(1/(SQRT(2*PI())*TRAINING!$U$9))*EXP(-((G10-TRAINING!$U$4)^2)/(2*(TRAINING!$U$9^2))) -> 0.61152593 | Y10: =(1/(SQRT(2*PI())*TRAINING!$V$8))*EXP(-((H10-TRAINING!$V$3)^2)/(2*(TRAINING!$V$8^2))) -> 0.0063439657 | Z10: =(1/(SQRT(2*PI())*TRAINING!$V$9))*EXP(-((H10-TRAINING!$V$4)^2)/(2*(TRAINING!$V$9^2))) -> 0.011878973 | AA10: =PRODUCT(K10,M10,O10,Q10,S10,U10,W10,Y10)*TRAINING!$L$2 -> 4.7058472e-21 | AB10: =PRODUCT(L10,N10,P10,R10,T10,V10,X10,Z10)*TRAINING!$L$3 -> 5.6225432e-17 | AC10: =IF(AB10>AA10,1,0) -> 1 | AD10: =IF(I10=AC10,1,0) -> 1 | AG10: =IF(AND(AC10=1,I10=1),"TP",IF(AND(AC10=0,I10=0),"TN",IF(AND(AC10=1,I10=0),"FP","FN"))) -> TP | AH10: RECAL | AI10: =(AI2/(AI2+AI5)) -> 0.57407407
A11: 8 | B11: 125 | C11: 96 | D11: 23 | E11: 30.5 | F11: 32 | G11: 0.232 | H11: 54 | I11: 1 | K11: =(1/(SQRT(2*PI())*TRAINING!$O$8))*EXP(-((A11-TRAINING!$O$3)^2)/(2*(TRAINING!$O$8^2))) -> 0.037889114 | L11: =(1/(SQRT(2*PI())*TRAINING!$O$9))*EXP(-((A11-TRAINING!$O$4)^2)/(2*(TRAINING!$O$9^2))) -> 0.074585526 | M11: =(1/(SQRT(2*PI())*TRAINING!$P$8))*EXP(-((B11-TRAINING!$P$3)^2)/(2*(TRAINING!$P$8^2))) -> 0.013849429 | N11: =(1/(SQRT(2*PI())*TRAINING!$P$9))*EXP(-((B11-TRAINING!$P$4)^2)/(2*(TRAINING!$P$9^2))) -> 0.011214812 | O11: =(1/(SQRT(2*PI())*TRAINING!$Q$8))*EXP(-((C11-TRAINING!$Q$3)^2)/(2*(TRAINING!$Q$8^2))) -> 0.0034342934 | P11: =(1/(SQRT(2*PI())*TRAINING!$Q$9))*EXP(-((C11-TRAINING!$Q$4)^2)/(2*(TRAINING!$Q$9^2))) -> 0.0066352618 | Q11: =(1/(SQRT(2*PI())*TRAINING!$R$8))*EXP(-((D11-TRAINING!$R$3)^2)/(2*(TRAINING!$R$8^2))) -> 0.042691938 | R11: =(1/(SQRT(2*PI())*TRAINING!$R$9))*EXP(-((D11-TRAINING!$R$4)^2)/(2*(TRAINING!$R$9^2))) -> 0.032020658 | S11: =(1/(SQRT(2*PI())*TRAINING!$S$8))*EXP(-((E11-TRAINING!$S$3)^2)/(2*(TRAINING!$S$8^2))) -> 0.0035657055 | T11: =(1/(SQRT(2*PI())*TRAINING!$S$9))*EXP(-((E11-TRAINING!$S$4)^2)/(2*(TRAINING!$S$9^2))) -> 0.0025951511 | U11: =(1/(SQRT(2*PI())*TRAINING!$T$8))*EXP(-((F11-TRAINING!$T$3)^2)/(2*(TRAINING!$T$8^2))) -> 0.060345164 | V11: =(1/(SQRT(2*PI())*TRAINING!$T$9))*EXP(-((F11-TRAINING!$T$4)^2)/(2*(TRAINING!$T$9^2))) -> 0.053444314 | W11: =(1/(SQRT(2*PI())*TRAINING!$U$8))*EXP(-((G11-TRAINING!$U$3)^2)/(2*(TRAINING!$U$8^2))) -> 1.0585568 | X11: =(1/(SQRT(2*PI())*TRAINING!$U$9))*EXP(-((G11-TRAINING!$U$4)^2)/(2*(TRAINING!$U$9^2))) -> 0.74873969 | Y11: =(1/(SQRT(2*PI())*TRAINING!$V$8))*EXP(-((H11-TRAINING!$V$3)^2)/(2*(TRAINING!$V$8^2))) -> 0.0054201138 | Z11: =(1/(SQRT(2*PI())*TRAINING!$V$9))*EXP(-((H11-TRAINING!$V$4)^2)/(2*(TRAINING!$V$9^2))) -> 0.010313205 | AA11: =PRODUCT(K11,M11,O11,Q11,S11,U11,W11,Y11)*TRAINING!$L$2 -> 6.1931185e-14 | AB11: =PRODUCT(L11,N11,P11,R11,T11,V11,X11,Z11)*TRAINING!$L$3 -> 6.4714628e-14 | AC11: =IF(AB11>AA11,1,0) -> 1 | AD11: =IF(I11=AC11,1,0) -> 1 | AG11: =IF(AND(AC11=1,I11=1),"TP",IF(AND(AC11=0,I11=0),"TN",IF(AND(AC11=1,I11=0),"FP","FN"))) -> TP | AH11: F1 SCORE | AI11: =(2*(AI9*AI10)/(AI9+AI10)) -> 0.62
A12: 4 | B12: 110 | C12: 92 | D12: 23 | E12: 30.5 | F12: 37.6 | G12: 0.191 | H12: 30 | I12: 0 | K12: =(1/(SQRT(2*PI())*TRAINING!$O$8))*EXP(-((A12-TRAINING!$O$3)^2)/(2*(TRAINING!$O$8^2))) -> 0.12757449 | L12: =(1/(SQRT(2*PI())*TRAINING!$O$9))*EXP(-((A12-TRAINING!$O$4)^2)/(2*(TRAINING!$O$9^2))) -> 0.10484388 | M12: =(1/(SQRT(2*PI())*TRAINING!$P$8))*EXP(-((B12-TRAINING!$P$3)^2)/(2*(TRAINING!$P$8^2))) -> 0.016155871 | N12: =(1/(SQRT(2*PI())*TRAINING!$P$9))*EXP(-((B12-TRAINING!$P$4)^2)/(2*(TRAINING!$P$9^2))) -> 0.007107907 | O12: =(1/(SQRT(2*PI())*TRAINING!$Q$8))*EXP(-((C12-TRAINING!$Q$3)^2)/(2*(TRAINING!$Q$8^2))) -> 0.0067740576 | P12: =(1/(SQRT(2*PI())*TRAINING!$Q$9))*EXP(-((C12-TRAINING!$Q$4)^2)/(2*(TRAINING!$Q$9^2))) -> 0.011931688 | Q12: =(1/(SQRT(2*PI())*TRAINING!$R$8))*EXP(-((D12-TRAINING!$R$3)^2)/(2*(TRAINING!$R$8^2))) -> 0.042691938 | R12: =(1/(SQRT(2*PI())*TRAINING!$R$9))*EXP(-((D12-TRAINING!$R$4)^2)/(2*(TRAINING!$R$9^2))) -> 0.032020658 | S12: =(1/(SQRT(2*PI())*TRAINING!$S$8))*EXP(-((E12-TRAINING!$S$3)^2)/(2*(TRAINING!$S$8^2))) -> 0.0035657055 | T12: =(1/(SQRT(2*PI())*TRAINING!$S$9))*EXP(-((E12-TRAINING!$S$4)^2)/(2*(TRAINING!$S$9^2))) -> 0.0025951511 | U12: =(1/(SQRT(2*PI())*TRAINING!$T$8))*EXP(-((F12-TRAINING!$T$3)^2)/(2*(TRAINING!$T$8^2))) -> 0.036466786 | V12: =(1/(SQRT(2*PI())*TRAINING!$T$9))*EXP(-((F12-TRAINING!$T$4)^2)/(2*(TRAINING!$T$9^2))) -> 0.057102368 | W12: =(1/(SQRT(2*PI())*TRAINING!$U$8))*EXP(-((G12-TRAINING!$U$3)^2)/(2*(TRAINING!$U$8^2))) -> 0.9574415 | X12: =(1/(SQRT(2*PI())*TRAINING!$U$9))*EXP(-((G12-TRAINING!$U$4)^2)/(2*(TRAINING!$U$9^2))) -> 0.67279153 | Y12: =(1/(SQRT(2*PI())*TRAINING!$V$8))*EXP(-((H12-TRAINING!$V$3)^2)/(2*(TRAINING!$V$8^2))) -> 0.033400484 | Z12: =(1/(SQRT(2*PI())*TRAINING!$V$9))*EXP(-((H12-TRAINING!$V$4)^2)/(2*(TRAINING!$V$9^2))) -> 0.030379462 | AA12: =PRODUCT(K12,M12,O12,Q12,S12,U12,W12,Y12)*TRAINING!$L$2 -> 1.6160925e-12 | AB12: =PRODUCT(L12,N12,P12,R12,T12,V12,X12,Z12)*TRAINING!$L$3 -> 2.9320627e-13 | AC12: =IF(AB12>AA12,1,0) -> 0 | AD12: =IF(I12=AC12,1,0) -> 1 | AG12: =IF(AND(AC12=1,I12=1),"TP",IF(AND(AC12=0,I12=0),"TN",IF(AND(AC12=1,I12=0),"FP","FN"))) -> TN
A13: 10 | B13: 168 | C13: 74 | D13: 23 | E13: 30.5 | F13: 38 | G13: 0.537 | H13: 34 | I13: 1 | K13: =(1/(SQRT(2*PI())*TRAINING!$O$8))*EXP(-((A13-TRAINING!$O$3)^2)/(2*(TRAINING!$O$8^2))) -> 0.010720214 | L13: =(1/(SQRT(2*PI())*TRAINING!$O$9))*EXP(-((A13-TRAINING!$O$4)^2)/(2*(TRAINING!$O$9^2))) -> 0.040698455 | M13: =(1/(SQRT(2*PI())*TRAINING!$P$8))*EXP(-((B13-TRAINING!$P$3)^2)/(2*(TRAINING!$P$8^2))) -> 0.0011460275 | N13: =(1/(SQRT(2*PI())*TRAINING!$P$9))*EXP(-((B13-TRAINING!$P$4)^2)/(2*(TRAINING!$P$9^2))) -> 0.0095762424 | O13: =(1/(SQRT(2*PI())*TRAINING!$Q$8))*EXP(-((C13-TRAINING!$Q$3)^2)/(2*(TRAINING!$Q$8^2))) -> 0.03324749 | P13: =(1/(SQRT(2*PI())*TRAINING!$Q$9))*EXP(-((C13-TRAINING!$Q$4)^2)/(2*(TRAINING!$Q$9^2))) -> 0.03514783 | Q13: =(1/(SQRT(2*PI())*TRAINING!$R$8))*EXP(-((D13-TRAINING!$R$3)^2)/(2*(TRAINING!$R$8^2))) -> 0.042691938 | R13: =(1/(SQRT(2*PI())*TRAINING!$R$9))*EXP(-((D13-TRAINING!$R$4)^2)/(2*(TRAINING!$R$9^2))) -> 0.032020658 | S13: =(1/(SQRT(2*PI())*TRAINING!$S$8))*EXP(-((E13-TRAINING!$S$3)^2)/(2*(TRAINING!$S$8^2))) -> 0.0035657055 | T13: =(1/(SQRT(2*PI())*TRAINING!$S$9))*EXP(-((E13-TRAINING!$S$4)^2)/(2*(TRAINING!$S$9^2))) -> 0.0025951511 | U13: =(1/(SQRT(2*PI())*TRAINING!$T$8))*EXP(-((F13-TRAINING!$T$3)^2)/(2*(TRAINING!$T$8^2))) -> 0.034201561 | V13: =(1/(SQRT(2*PI())*TRAINING!$T$9))*EXP(-((F13-TRAINING!$T$4)^2)/(2*(TRAINING!$T$9^2))) -> 0.055802758 | W13: =(1/(SQRT(2*PI())*TRAINING!$U$8))*EXP(-((G13-TRAINING!$U$3)^2)/(2*(TRAINING!$U$8^2))) -> 1.2487814 | X13: =(1/(SQRT(2*PI())*TRAINING!$U$9))*EXP(-((G13-TRAINING!$U$4)^2)/(2*(TRAINING!$U$9^2))) -> 1.1056398 | Y13: =(1/(SQRT(2*PI())*TRAINING!$V$8))*EXP(-((H13-TRAINING!$V$3)^2)/(2*(TRAINING!$V$8^2))) -> 0.032765784 | Z13: =(1/(SQRT(2*PI())*TRAINING!$V$9))*EXP(-((H13-TRAINING!$V$4)^2)/(2*(TRAINING!$V$9^2))) -> 0.035473017 | AA13: =PRODUCT(K13,M13,O13,Q13,S13,U13,W13,Y13)*TRAINING!$L$2 -> 5.6737587e-14 | AB13: =PRODUCT(L13,N13,P13,R13,T13,V13,X13,Z13)*TRAINING!$L$3 -> 8.470535e-13 | AC13: =IF(AB13>AA13,1,0) -> 1 | AD13: =IF(I13=AC13,1,0) -> 1 | AG13: =IF(AND(AC13=1,I13=1),"TP",IF(AND(AC13=0,I13=0),"TN",IF(AND(AC13=1,I13=0),"FP","FN"))) -> TP
A14: 10 | B14: 139 | C14: 80 | D14: 23 | E14: 30.5 | F14: 27.1 | G14: 1.441 | H14: 57 | I14: 0 | K14: =(1/(SQRT(2*PI())*TRAINING!$O$8))*EXP(-((A14-TRAINING!$O$3)^2)/(2*(TRAINING!$O$8^2))) -> 0.010720214 | L14: =(1/(SQRT(2*PI())*TRAINING!$O$9))*EXP(-((A14-TRAINING!$O$4)^2)/(2*(TRAINING!$O$9^2))) -> 0.040698455 | M14: =(1/(SQRT(2*PI())*TRAINING!$P$8))*EXP(-((B14-TRAINING!$P$3)^2)/(2*(TRAINING!$P$8^2))) -> 0.0085908173 | N14: =(1/(SQRT(2*PI())*TRAINING!$P$9))*EXP(-((B14-TRAINING!$P$4)^2)/(2*(TRAINING!$P$9^2))) -> 0.013522236 | O14: =(1/(SQRT(2*PI())*TRAINING!$Q$8))*EXP(-((C14-TRAINING!$Q$3)^2)/(2*(TRAINING!$Q$8^2))) -> 0.025539276 | P14: =(1/(SQRT(2*PI())*TRAINING!$Q$9))*EXP(-((C14-TRAINING!$Q$4)^2)/(2*(TRAINING!$Q$9^2))) -> 0.032561151 | Q14: =(1/(SQRT(2*PI())*TRAINING!$R$8))*EXP(-((D14-TRAINING!$R$3)^2)/(2*(TRAINING!$R$8^2))) -> 0.042691938 | R14: =(1/(SQRT(2*PI())*TRAINING!$R$9))*EXP(-((D14-TRAINING!$R$4)^2)/(2*(TRAINING!$R$9^2))) -> 0.032020658 | S14: =(1/(SQRT(2*PI())*TRAINING!$S$8))*EXP(-((E14-TRAINING!$S$3)^2)/(2*(TRAINING!$S$8^2))) -> 0.0035657055 | T14: =(1/(SQRT(2*PI())*TRAINING!$S$9))*EXP(-((E14-TRAINING!$S$4)^2)/(2*(TRAINING!$S$9^2))) -> 0.0025951511 | U14: =(1/(SQRT(2*PI())*TRAINING!$T$8))*EXP(-((F14-TRAINING!$T$3)^2)/(2*(TRAINING!$T$8^2))) -> 0.051277842 | V14: =(1/(SQRT(2*PI())*TRAINING!$T$9))*EXP(-((F14-TRAINING!$T$4)^2)/(2*(TRAINING!$T$9^2))) -> 0.027821051 | W14: =(1/(SQRT(2*PI())*TRAINING!$U$8))*EXP(-((G14-TRAINING!$U$3)^2)/(2*(TRAINING!$U$8^2))) -> 0.0049351169 | X14: =(1/(SQRT(2*PI())*TRAINING!$U$9))*EXP(-((G14-TRAINING!$U$4)^2)/(2*(TRAINING!$U$9^2))) -> 0.05246509 | Y14: =(1/(SQRT(2*PI())*TRAINING!$V$8))*EXP(-((H14-TRAINING!$V$3)^2)/(2*(TRAINING!$V$8^2))) -> 0.0032393461 | Z14: =(1/(SQRT(2*PI())*TRAINING!$V$9))*EXP(-((H14-TRAINING!$V$4)^2)/(2*(TRAINING!$V$9^2))) -> 0.0064181614 | AA14: =PRODUCT(K14,M14,O14,Q14,S14,U14,W14,Y14)*TRAINING!$L$2 -> 1.9137784e-16 | AB14: =PRODUCT(L14,N14,P14,R14,T14,V14,X14,Z14)*TRAINING!$L$3 -> 4.7429942e-15 | AC14: =IF(AB14>AA14,1,0) -> 1 | AD14: =IF(I14=AC14,1,0) -> 0 | AG14: =IF(AND(AC14=1,I14=1),"TP",IF(AND(AC14=0,I14=0),"TN",IF(AND(AC14=1,I14=0),"FP","FN"))) -> FP
A15: 1 | B15: 189 | C15: 60 | D15: 23 | E15: 846 | F15: 30.1 | G15: 0.398 | H15: 59 | I15: 1 | K15: =(1/(SQRT(2*PI())*TRAINING!$O$8))*EXP(-((A15-TRAINING!$O$3)^2)/(2*(TRAINING!$O$8^2))) -> 0.10069315 | L15: =(1/(SQRT(2*PI())*TRAINING!$O$9))*EXP(-((A15-TRAINING!$O$4)^2)/(2*(TRAINING!$O$9^2))) -> 0.0631652 | M15: =(1/(SQRT(2*PI())*TRAINING!$P$8))*EXP(-((B15-TRAINING!$P$3)^2)/(2*(TRAINING!$P$8^2))) -> 0.00011240799 | N15: =(1/(SQRT(2*PI())*TRAINING!$P$9))*EXP(-((B15-TRAINING!$P$4)^2)/(2*(TRAINING!$P$9^2))) -> 0.0040250796 | O15: =(1/(SQRT(2*PI())*TRAINING!$Q$8))*EXP(-((C15-TRAINING!$Q$3)^2)/(2*(TRAINING!$Q$8^2))) -> 0.021821879 | P15: =(1/(SQRT(2*PI())*TRAINING!$Q$9))*EXP(-((C15-TRAINING!$Q$4)^2)/(2*(TRAINING!$Q$9^2))) -> 0.013939617 | Q15: =(1/(SQRT(2*PI())*TRAINING!$R$8))*EXP(-((D15-TRAINING!$R$3)^2)/(2*(TRAINING!$R$8^2))) -> 0.042691938 | R15: =(1/(SQRT(2*PI())*TRAINING!$R$9))*EXP(-((D15-TRAINING!$R$4)^2)/(2*(TRAINING!$R$9^2))) -> 0.032020658 | S15: =(1/(SQRT(2*PI())*TRAINING!$S$8))*EXP(-((E15-TRAINING!$S$3)^2)/(2*(TRAINING!$S$8^2))) -> 2.3788757e-17 | T15: =(1/(SQRT(2*PI())*TRAINING!$S$9))*EXP(-((E15-TRAINING!$S$4)^2)/(2*(TRAINING!$S$9^2))) -> 3.9135823e-11 | U15: =(1/(SQRT(2*PI())*TRAINING!$T$8))*EXP(-((F15-TRAINING!$T$3)^2)/(2*(TRAINING!$T$8^2))) -> 0.060570643 | V15: =(1/(SQRT(2*PI())*TRAINING!$T$9))*EXP(-((F15-TRAINING!$T$4)^2)/(2*(TRAINING!$T$9^2))) -> 0.044318608 | W15: =(1/(SQRT(2*PI())*TRAINING!$U$8))*EXP(-((G15-TRAINING!$U$3)^2)/(2*(TRAINING!$U$8^2))) -> 1.3152375 | X15: =(1/(SQRT(2*PI())*TRAINING!$U$9))*EXP(-((G15-TRAINING!$U$4)^2)/(2*(TRAINING!$U$9^2))) -> 1.0115903 | Y15: =(1/(SQRT(2*PI())*TRAINING!$V$8))*EXP(-((H15-TRAINING!$V$3)^2)/(2*(TRAINING!$V$8^2))) -> 0.0022182568 | Z15: =(1/(SQRT(2*PI())*TRAINING!$V$9))*EXP(-((H15-TRAINING!$V$4)^2)/(2*(TRAINING!$V$9^2))) -> 0.0044864118 | AA15: =PRODUCT(K15,M15,O15,Q15,S15,U15,W15,Y15)*TRAINING!$L$2 -> 2.8903759e-29 | AB15: =PRODUCT(L15,N15,P15,R15,T15,V15,X15,Z15)*TRAINING!$L$3 -> 3.0372234e-22 | AC15: =IF(AB15>AA15,1,0) -> 1 | AD15: =IF(I15=AC15,1,0) -> 1 | AG15: =IF(AND(AC15=1,I15=1),"TP",IF(AND(AC15=0,I15=0),"TN",IF(AND(AC15=1,I15=0),"FP","FN"))) -> TP
A16: 5 | B16: 166 | C16: 72 | D16: 19 | E16: 175 | F16: 25.8 | G16: 0.587 | H16: 51 | I16: 1 | K16: =(1/(SQRT(2*PI())*TRAINING!$O$8))*EXP(-((A16-TRAINING!$O$3)^2)/(2*(TRAINING!$O$8^2))) -> 0.11094892 | L16: =(1/(SQRT(2*PI())*TRAINING!$O$9))*EXP(-((A16-TRAINING!$O$4)^2)/(2*(TRAINING!$O$9^2))) -> 0.10736286 | M16: =(1/(SQRT(2*PI())*TRAINING!$P$8))*EXP(-((B16-TRAINING!$P$3)^2)/(2*(TRAINING!$P$8^2))) -> 0.001376604 | N16: =(1/(SQRT(2*PI())*TRAINING!$P$9))*EXP(-((B16-TRAINING!$P$4)^2)/(2*(TRAINING!$P$9^2))) -> 0.010122968 | O16: =(1/(SQRT(2*PI())*TRAINING!$Q$8))*EXP(-((C16-TRAINING!$Q$3)^2)/(2*(TRAINING!$Q$8^2))) -> 0.034215224 | P16: =(1/(SQRT(2*PI())*TRAINING!$Q$9))*EXP(-((C16-TRAINING!$Q$4)^2)/(2*(TRAINING!$Q$9^2))) -> 0.033852207 | Q16: =(1/(SQRT(2*PI())*TRAINING!$R$8))*EXP(-((D16-TRAINING!$R$3)^2)/(2*(TRAINING!$R$8^2))) -> 0.032766196 | R16: =(1/(SQRT(2*PI())*TRAINING!$R$9))*EXP(-((D16-TRAINING!$R$4)^2)/(2*(TRAINING!$R$9^2))) -> 0.022363588 | S16: =(1/(SQRT(2*PI())*TRAINING!$S$8))*EXP(-((E16-TRAINING!$S$3)^2)/(2*(TRAINING!$S$8^2))) -> 0.0027175037 | T16: =(1/(SQRT(2*PI())*TRAINING!$S$9))*EXP(-((E16-TRAINING!$S$4)^2)/(2*(TRAINING!$S$9^2))) -> 0.0029022423 | U16: =(1/(SQRT(2*PI())*TRAINING!$T$8))*EXP(-((F16-TRAINING!$T$3)^2)/(2*(TRAINING!$T$8^2))) -> 0.044679381 | V16: =(1/(SQRT(2*PI())*TRAINING!$T$9))*EXP(-((F16-TRAINING!$T$4)^2)/(2*(TRAINING!$T$9^2))) -> 0.021314565 | W16: =(1/(SQRT(2*PI())*TRAINING!$U$8))*EXP(-((G16-TRAINING!$U$3)^2)/(2*(TRAINING!$U$8^2))) -> 1.1635047 | X16: =(1/(SQRT(2*PI())*TRAINING!$U$9))*EXP(-((G16-TRAINING!$U$4)^2)/(2*(TRAINING!$U$9^2))) -> 1.1008238 | Y16: =(1/(SQRT(2*PI())*TRAINING!$V$8))*EXP(-((H16-TRAINING!$V$3)^2)/(2*(TRAINING!$V$8^2))) -> 0.0085078298 | Z16: =(1/(SQRT(2*PI())*TRAINING!$V$9))*EXP(-((H16-TRAINING!$V$4)^2)/(2*(TRAINING!$V$9^2))) -> 0.015368647 | AA16: =PRODUCT(K16,M16,O16,Q16,S16,U16,W16,Y16)*TRAINING!$L$2 -> 1.3418716e-13 | AB16: =PRODUCT(L16,N16,P16,R16,T16,V16,X16,Z16)*TRAINING!$L$3 -> 2.9277428e-13 | AC16: =IF(AB16>AA16,1,0) -> 1 | AD16: =IF(I16=AC16,1,0) -> 1 | AG16: =IF(AND(AC16=1,I16=1),"TP",IF(AND(AC16=0,I16=0),"TN",IF(AND(AC16=1,I16=0),"FP","FN"))) -> TP
A17: 7 | B17: 100 | C17: 72 | D17: 23 | E17: 30.5 | F17: 30 | G17: 0.484 | H17: 32 | I17: 1 | K17: =(1/(SQRT(2*PI())*TRAINING!$O$8))*EXP(-((A17-TRAINING!$O$3)^2)/(2*(TRAINING!$O$8^2))) -> 0.060464209 | L17: =(1/(SQRT(2*PI())*TRAINING!$O$9))*EXP(-((A17-TRAINING!$O$4)^2)/(2*(TRAINING!$O$9^2))) -> 0.090554447 | M17: =(1/(SQRT(2*PI())*TRAINING!$P$8))*EXP(-((B17-TRAINING!$P$3)^2)/(2*(TRAINING!$P$8^2))) -> 0.01457703 | N17: =(1/(SQRT(2*PI())*TRAINING!$P$9))*EXP(-((B17-TRAINING!$P$4)^2)/(2*(TRAINING!$P$9^2))) -> 0.0045281526 | O17: =(1/(SQRT(2*PI())*TRAINING!$Q$8))*EXP(-((C17-TRAINING!$Q$3)^2)/(2*(TRAINING!$Q$8^2))) -> 0.034215224 | P17: =(1/(SQRT(2*PI())*TRAINING!$Q$9))*EXP(-((C17-TRAINING!$Q$4)^2)/(2*(TRAINING!$Q$9^2))) -> 0.033852207 | Q17: =(1/(SQRT(2*PI())*TRAINING!$R$8))*EXP(-((D17-TRAINING!$R$3)^2)/(2*(TRAINING!$R$8^2))) -> 0.042691938 | R17: =(1/(SQRT(2*PI())*TRAINING!$R$9))*EXP(-((D17-TRAINING!$R$4)^2)/(2*(TRAINING!$R$9^2))) -> 0.032020658 | S17: =(1/(SQRT(2*PI())*TRAINING!$S$8))*EXP(-((E17-TRAINING!$S$3)^2)/(2*(TRAINING!$S$8^2))) -> 0.0035657055 | T17: =(1/(SQRT(2*PI())*TRAINING!$S$9))*EXP(-((E17-TRAINING!$S$4)^2)/(2*(TRAINING!$S$9^2))) -> 0.0025951511 | U17: =(1/(SQRT(2*PI())*TRAINING!$T$8))*EXP(-((F17-TRAINING!$T$3)^2)/(2*(TRAINING!$T$8^2))) -> 0.060440566 | V17: =(1/(SQRT(2*PI())*TRAINING!$T$9))*EXP(-((F17-TRAINING!$T$4)^2)/(2*(TRAINING!$T$9^2))) -> 0.043782646 | W17: =(1/(SQRT(2*PI())*TRAINING!$U$8))*EXP(-((G17-TRAINING!$U$3)^2)/(2*(TRAINING!$U$8^2))) -> 1.3061161 | X17: =(1/(SQRT(2*PI())*TRAINING!$U$9))*EXP(-((G17-TRAINING!$U$4)^2)/(2*(TRAINING!$U$9^2))) -> 1.0876903 | Y17: =(1/(SQRT(2*PI())*TRAINING!$V$8))*EXP(-((H17-TRAINING!$V$3)^2)/(2*(TRAINING!$V$8^2))) -> 0.033554537 | Z17: =(1/(SQRT(2*PI())*TRAINING!$V$9))*EXP(-((H17-TRAINING!$V$4)^2)/(2*(TRAINING!$V$9^2))) -> 0.033382195 | AA17: =PRODUCT(K17,M17,O17,Q17,S17,U17,W17,Y17)*TRAINING!$L$2 -> 7.9288278e-12 | AB17: =PRODUCT(L17,N17,P17,R17,T17,V17,X17,Z17)*TRAINING!$L$3 -> 6.2346462e-13 | AC17: =IF(AB17>AA17,1,0) -> 0 | AD17: =IF(I17=AC17,1,0) -> 0 | AG17: =IF(AND(AC17=1,I17=1),"TP",IF(AND(AC17=0,I17=0),"TN",IF(AND(AC17=1,I17=0),"FP","FN"))) -> FN
A18: 0 | B18: 118 | C18: 84 | D18: 47 | E18: 230 | F18: 45.8 | G18: 0.551 | H18: 31 | I18: 1 | K18: =(1/(SQRT(2*PI())*TRAINING!$O$8))*EXP(-((A18-TRAINING!$O$3)^2)/(2*(TRAINING!$O$8^2))) -> 0.074791087 | L18: =(1/(SQRT(2*PI())*TRAINING!$O$9))*EXP(-((A18-TRAINING!$O$4)^2)/(2*(TRAINING!$O$9^2))) -> 0.046140116 | M18: =(1/(SQRT(2*PI())*TRAINING!$P$8))*EXP(-((B18-TRAINING!$P$3)^2)/(2*(TRAINING!$P$8^2))) -> 0.0155828 | N18: =(1/(SQRT(2*PI())*TRAINING!$P$9))*EXP(-((B18-TRAINING!$P$4)^2)/(2*(TRAINING!$P$9^2))) -> 0.0093682153 | O18: =(1/(SQRT(2*PI())*TRAINING!$Q$8))*EXP(-((C18-TRAINING!$Q$3)^2)/(2*(TRAINING!$Q$8^2))) -> 0.018472874 | P18: =(1/(SQRT(2*PI())*TRAINING!$Q$9))*EXP(-((C18-TRAINING!$Q$4)^2)/(2*(TRAINING!$Q$9^2))) -> 0.026431555 | Q18: =(1/(SQRT(2*PI())*TRAINING!$R$8))*EXP(-((D18-TRAINING!$R$3)^2)/(2*(TRAINING!$R$8^2))) -> 0.0026728517 | R18: =(1/(SQRT(2*PI())*TRAINING!$R$9))*EXP(-((D18-TRAINING!$R$4)^2)/(2*(TRAINING!$R$9^2))) -> 0.0087544728 | S18: =(1/(SQRT(2*PI())*TRAINING!$S$8))*EXP(-((E18-TRAINING!$S$3)^2)/(2*(TRAINING!$S$8^2))) -> 0.001313298 | T18: =(1/(SQRT(2*PI())*TRAINING!$S$9))*EXP(-((E18-TRAINING!$S$4)^2)/(2*(TRAINING!$S$9^2))) -> 0.0020839406 | U18: =(1/(SQRT(2*PI())*TRAINING!$T$8))*EXP(-((F18-TRAINING!$T$3)^2)/(2*(TRAINING!$T$8^2))) -> 0.004624801 | V18: =(1/(SQRT(2*PI())*TRAINING!$T$9))*EXP(-((F18-TRAINING!$T$4)^2)/(2*(TRAINING!$T$9^2))) -> 0.017001767 | W18: =(1/(SQRT(2*PI())*TRAINING!$U$8))*EXP(-((G18-TRAINING!$U$3)^2)/(2*(TRAINING!$U$8^2))) -> 1.2276981 | X18: =(1/(SQRT(2*PI())*TRAINING!$U$9))*EXP(-((G18-TRAINING!$U$4)^2)/(2*(TRAINING!$U$9^2))) -> 1.1064317 | Y18: =(1/(SQRT(2*PI())*TRAINING!$V$8))*EXP(-((H18-TRAINING!$V$3)^2)/(2*(TRAINING!$V$8^2))) -> 0.033596432 | Z18: =(1/(SQRT(2*PI())*TRAINING!$V$9))*EXP(-((H18-TRAINING!$V$4)^2)/(2*(TRAINING!$V$9^2))) -> 0.031979114 | AA18: =PRODUCT(K18,M18,O18,Q18,S18,U18,W18,Y18)*TRAINING!$L$2 -> 9.3997221e-15 | AB18: =PRODUCT(L18,N18,P18,R18,T18,V18,X18,Z18)*TRAINING!$L$3 -> 4.2632189e-14 | AC18: =IF(AB18>AA18,1,0) -> 1 | AD18: =IF(I18=AC18,1,0) -> 1 | AG18: =IF(AND(AC18=1,I18=1),"TP",IF(AND(AC18=0,I18=0),"TN",IF(AND(AC18=1,I18=0),"FP","FN"))) -> TP
A19: 7 | B19: 107 | C19: 74 | D19: 23 | E19: 30.5 | F19: 29.6 | G19: 0.254 | H19: 31 | I19: 1 | K19: =(1/(SQRT(2*PI())*TRAINING!$O$8))*EXP(-((A19-TRAINING!$O$3)^2)/(2*(TRAINING!$O$8^2))) -> 0.060464209 | L19: =(1/(SQRT(2*PI())*TRAINING!$O$9))*EXP(-((A19-TRAINING!$O$4)^2)/(2*(TRAINING!$O$9^2))) -> 0.090554447 | M19: =(1/(SQRT(2*PI())*TRAINING!$P$8))*EXP(-((B19-TRAINING!$P$3)^2)/(2*(TRAINING!$P$8^2))) -> 0.015937854 | N19: =(1/(SQRT(2*PI())*TRAINING!$P$9))*EXP(-((B19-TRAINING!$P$4)^2)/(2*(TRAINING!$P$9^2))) -> 0.0062857001 | O19: =(1/(SQRT(2*PI())*TRAINING!$Q$8))*EXP(-((C19-TRAINING!$Q$3)^2)/(2*(TRAINING!$Q$8^2))) -> 0.03324749 | P19: =(1/(SQRT(2*PI())*TRAINING!$Q$9))*EXP(-((C19-TRAINING!$Q$4)^2)/(2*(TRAINING!$Q$9^2))) -> 0.03514783 | Q19: =(1/(SQRT(2*PI())*TRAINING!$R$8))*EXP(-((D19-TRAINING!$R$3)^2)/(2*(TRAINING!$R$8^2))) -> 0.042691938 | R19: =(1/(SQRT(2*PI())*TRAINING!$R$9))*EXP(-((D19-TRAINING!$R$4)^2)/(2*(TRAINING!$R$9^2))) -> 0.032020658 | S19: =(1/(SQRT(2*PI())*TRAINING!$S$8))*EXP(-((E19-TRAINING!$S$3)^2)/(2*(TRAINING!$S$8^2))) -> 0.0035657055 | T19: =(1/(SQRT(2*PI())*TRAINING!$S$9))*EXP(-((E19-TRAINING!$S$4)^2)/(2*(TRAINING!$S$9^2))) -> 0.0025951511 | U19: =(1/(SQRT(2*PI())*TRAINING!$T$8))*EXP(-((F19-TRAINING!$T$3)^2)/(2*(TRAINING!$T$8^2))) -> 0.059782623 | V19: =(1/(SQRT(2*PI())*TRAINING!$T$9))*EXP(-((F19-TRAINING!$T$4)^2)/(2*(TRAINING!$T$9^2))) -> 0.041606503 | W19: =(1/(SQRT(2*PI())*TRAINING!$U$8))*EXP(-((G19-TRAINING!$U$3)^2)/(2*(TRAINING!$U$8^2))) -> 1.1086462 | X19: =(1/(SQRT(2*PI())*TRAINING!$U$9))*EXP(-((G19-TRAINING!$U$4)^2)/(2*(TRAINING!$U$9^2))) -> 0.78875196 | Y19: =(1/(SQRT(2*PI())*TRAINING!$V$8))*EXP(-((H19-TRAINING!$V$3)^2)/(2*(TRAINING!$V$8^2))) -> 0.033596432 | Z19: =(1/(SQRT(2*PI())*TRAINING!$V$9))*EXP(-((H19-TRAINING!$V$4)^2)/(2*(TRAINING!$V$9^2))) -> 0.031979114 | AA19: =PRODUCT(K19,M19,O19,Q19,S19,U19,W19,Y19)*TRAINING!$L$2 -> 7.0812314e-12 | AB19: =PRODUCT(L19,N19,P19,R19,T19,V19,X19,Z19)*TRAINING!$L$3 -> 5.9320101e-13 | AC19: =IF(AB19>AA19,1,0) -> 0 | AD19: =IF(I19=AC19,1,0) -> 0 | AG19: =IF(AND(AC19=1,I19=1),"TP",IF(AND(AC19=0,I19=0),"TN",IF(AND(AC19=1,I19=0),"FP","FN"))) -> FN
A20: 1 | B20: 103 | C20: 30 | D20: 38 | E20: 83 | F20: 43.3 | G20: 0.183 | H20: 33 | I20: 0 | K20: =(1/(SQRT(2*PI())*TRAINING!$O$8))*EXP(-((A20-TRAINING!$O$3)^2)/(2*(TRAINING!$O$8^2))) -> 0.10069315 | L20: =(1/(SQRT(2*PI())*TRAINING!$O$9))*EXP(-((A20-TRAINING!$O$4)^2)/(2*(TRAINING!$O$9^2))) -> 0.0631652 | M20: =(1/(SQRT(2*PI())*TRAINING!$P$8))*EXP(-((B20-TRAINING!$P$3)^2)/(2*(TRAINING!$P$8^2))) -> 0.015295558 | N20: =(1/(SQRT(2*PI())*TRAINING!$P$9))*EXP(-((B20-TRAINING!$P$4)^2)/(2*(TRAINING!$P$9^2))) -> 0.0052483814 | O20: =(1/(SQRT(2*PI())*TRAINING!$Q$8))*EXP(-((C20-TRAINING!$Q$3)^2)/(2*(TRAINING!$Q$8^2))) -> 6.6818368e-05 | P20: =(1/(SQRT(2*PI())*TRAINING!$Q$9))*EXP(-((C20-TRAINING!$Q$4)^2)/(2*(TRAINING!$Q$9^2))) -> 1.0590312e-05 | Q20: =(1/(SQRT(2*PI())*TRAINING!$R$8))*EXP(-((D20-TRAINING!$R$3)^2)/(2*(TRAINING!$R$8^2))) -> 0.018134563 | R20: =(1/(SQRT(2*PI())*TRAINING!$R$9))*EXP(-((D20-TRAINING!$R$4)^2)/(2*(TRAINING!$R$9^2))) -> 0.028475715 | S20: =(1/(SQRT(2*PI())*TRAINING!$S$8))*EXP(-((E20-TRAINING!$S$3)^2)/(2*(TRAINING!$S$8^2))) -> 0.0042513956 | T20: =(1/(SQRT(2*PI())*TRAINING!$S$9))*EXP(-((E20-TRAINING!$S$4)^2)/(2*(TRAINING!$S$9^2))) -> 0.0031861652 | U20: =(1/(SQRT(2*PI())*TRAINING!$T$8))*EXP(-((F20-TRAINING!$T$3)^2)/(2*(TRAINING!$T$8^2))) -> 0.010259032 | V20: =(1/(SQRT(2*PI())*TRAINING!$T$9))*EXP(-((F20-TRAINING!$T$4)^2)/(2*(TRAINING!$T$9^2))) -> 0.029004726 | W20: =(1/(SQRT(2*PI())*TRAINING!$U$8))*EXP(-((G20-TRAINING!$U$3)^2)/(2*(TRAINING!$U$8^2))) -> 0.9368419 | X20: =(1/(SQRT(2*PI())*TRAINING!$U$9))*EXP(-((G20-TRAINING!$U$4)^2)/(2*(TRAINING!$U$9^2))) -> 0.65790364 | Y20: =(1/(SQRT(2*PI())*TRAINING!$V$8))*EXP(-((H20-TRAINING!$V$3)^2)/(2*(TRAINING!$V$8^2))) -> 0.033275689 | Z20: =(1/(SQRT(2*PI())*TRAINING!$V$9))*EXP(-((H20-TRAINING!$V$4)^2)/(2*(TRAINING!$V$9^2))) -> 0.034556158 | AA20: =PRODUCT(K20,M20,O20,Q20,S20,U20,W20,Y20)*TRAINING!$L$2 -> 1.6545074e-15 | AB20: =PRODUCT(L20,N20,P20,R20,T20,V20,X20,Z20)*TRAINING!$L$3 -> 7.1415151e-17 | AC20: =IF(AB20>AA20,1,0) -> 0 | AD20: =IF(I20=AC20,1,0) -> 1 | AG20: =IF(AND(AC20=1,I20=1),"TP",IF(AND(AC20=0,I20=0),"TN",IF(AND(AC20=1,I20=0),"FP","FN"))) -> TN
A21: 1 | B21: 115 | C21: 70 | D21: 30 | E21: 96 | F21: 34.6 | G21: 0.529 | H21: 32 | I21: 1 | K21: =(1/(SQRT(2*PI())*TRAINING!$O$8))*EXP(-((A21-TRAINING!$O$3)^2)/(2*(TRAINING!$O$8^2))) -> 0.10069315 | L21: =(1/(SQRT(2*PI())*TRAINING!$O$9))*EXP(-((A21-TRAINING!$O$4)^2)/(2*(TRAINING!$O$9^2))) -> 0.0631652 | M21: =(1/(SQRT(2*PI())*TRAINING!$P$8))*EXP(-((B21-TRAINING!$P$3)^2)/(2*(TRAINING!$P$8^2))) -> 0.01599127 | N21: =(1/(SQRT(2*PI())*TRAINING!$P$9))*EXP(-((B21-TRAINING!$P$4)^2)/(2*(TRAINING!$P$9^2))) -> 0.0085214975 | O21: =(1/(SQRT(2*PI())*TRAINING!$Q$8))*EXP(-((C21-TRAINING!$Q$3)^2)/(2*(TRAINING!$Q$8^2))) -> 0.034183653 | P21: =(1/(SQRT(2*PI())*TRAINING!$Q$9))*EXP(-((C21-TRAINING!$Q$4)^2)/(2*(TRAINING!$Q$9^2))) -> 0.031592685 | Q21: =(1/(SQRT(2*PI())*TRAINING!$R$8))*EXP(-((D21-TRAINING!$R$3)^2)/(2*(TRAINING!$R$8^2))) -> 0.041168207 | R21: =(1/(SQRT(2*PI())*TRAINING!$R$9))*EXP(-((D21-TRAINING!$R$4)^2)/(2*(TRAINING!$R$9^2))) -> 0.040413708 | S21: =(1/(SQRT(2*PI())*TRAINING!$S$8))*EXP(-((E21-TRAINING!$S$3)^2)/(2*(TRAINING!$S$8^2))) -> 0.0042308076 | T21: =(1/(SQRT(2*PI())*TRAINING!$S$9))*EXP(-((E21-TRAINING!$S$4)^2)/(2*(TRAINING!$S$9^2))) -> 0.0032563778 | U21: =(1/(SQRT(2*PI())*TRAINING!$T$8))*EXP(-((F21-TRAINING!$T$3)^2)/(2*(TRAINING!$T$8^2))) -> 0.052338322 | V21: =(1/(SQRT(2*PI())*TRAINING!$T$9))*EXP(-((F21-TRAINING!$T$4)^2)/(2*(TRAINING!$T$9^2))) -> 0.060314349 | W21: =(1/(SQRT(2*PI())*TRAINING!$U$8))*EXP(-((G21-TRAINING!$U$3)^2)/(2*(TRAINING!$U$8^2))) -> 1.2597685 | X21: =(1/(SQRT(2*PI())*TRAINING!$U$9))*EXP(-((G21-TRAINING!$U$4)^2)/(2*(TRAINING!$U$9^2))) -> 1.1044396 | Y21: =(1/(SQRT(2*PI())*TRAINING!$V$8))*EXP(-((H21-TRAINING!$V$3)^2)/(2*(TRAINING!$V$8^2))) -> 0.033554537 | Z21: =(1/(SQRT(2*PI())*TRAINING!$V$9))*EXP(-((H21-TRAINING!$V$4)^2)/(2*(TRAINING!$V$9^2))) -> 0.033382195 | AA21: =PRODUCT(K21,M21,O21,Q21,S21,U21,W21,Y21)*TRAINING!$L$2 -> 1.3829855e-11 | AB21: =PRODUCT(L21,N21,P21,R21,T21,V21,X21,Z21)*TRAINING!$L$3 -> 1.6919996e-12 | AC21: =IF(AB21>AA21,1,0) -> 0 | AD21: =IF(I21=AC21,1,0) -> 0 | AG21: =IF(AND(AC21=1,I21=1),"TP",IF(AND(AC21=0,I21=0),"TN",IF(AND(AC21=1,I21=0),"FP","FN"))) -> FN
A22: 3 | B22: 126 | C22: 88 | D22: 41 | E22: 235 | F22: 39.3 | G22: 0.704 | H22: 27 | I22: 0 | K22: =(1/(SQRT(2*PI())*TRAINING!$O$8))*EXP(-((A22-TRAINING!$O$3)^2)/(2*(TRAINING!$O$8^2))) -> 0.13150944 | L22: =(1/(SQRT(2*PI())*TRAINING!$O$9))*EXP(-((A22-TRAINING!$O$4)^2)/(2*(TRAINING!$O$9^2))) -> 0.095216033 | M22: =(1/(SQRT(2*PI())*TRAINING!$P$8))*EXP(-((B22-TRAINING!$P$3)^2)/(2*(TRAINING!$P$8^2))) -> 0.013528801 | N22: =(1/(SQRT(2*PI())*TRAINING!$P$9))*EXP(-((B22-TRAINING!$P$4)^2)/(2*(TRAINING!$P$9^2))) -> 0.011452834 | O22: =(1/(SQRT(2*PI())*TRAINING!$Q$8))*EXP(-((C22-TRAINING!$Q$3)^2)/(2*(TRAINING!$Q$8^2))) -> 0.011869012 | P22: =(1/(SQRT(2*PI())*TRAINING!$Q$9))*EXP(-((C22-TRAINING!$Q$4)^2)/(2*(TRAINING!$Q$9^2))) -> 0.018914293 | Q22: =(1/(SQRT(2*PI())*TRAINING!$R$8))*EXP(-((D22-TRAINING!$R$3)^2)/(2*(TRAINING!$R$8^2))) -> 0.010765448 | R22: =(1/(SQRT(2*PI())*TRAINING!$R$9))*EXP(-((D22-TRAINING!$R$4)^2)/(2*(TRAINING!$R$9^2))) -> 0.021079762 | S22: =(1/(SQRT(2*PI())*TRAINING!$S$8))*EXP(-((E22-TRAINING!$S$3)^2)/(2*(TRAINING!$S$8^2))) -> 0.0012085003 | T22: =(1/(SQRT(2*PI())*TRAINING!$S$9))*EXP(-((E22-TRAINING!$S$4)^2)/(2*(TRAINING!$S$9^2))) -> 0.0020015654 | U22: =(1/(SQRT(2*PI())*TRAINING!$T$8))*EXP(-((F22-TRAINING!$T$3)^2)/(2*(TRAINING!$T$8^2))) -> 0.027056362 | V22: =(1/(SQRT(2*PI())*TRAINING!$T$9))*EXP(-((F22-TRAINING!$T$4)^2)/(2*(TRAINING!$T$9^2))) -> 0.050473402 | W22: =(1/(SQRT(2*PI())*TRAINING!$U$8))*EXP(-((G22-TRAINING!$U$3)^2)/(2*(TRAINING!$U$8^2))) -> 0.88536269 | X22: =(1/(SQRT(2*PI())*TRAINING!$U$9))*EXP(-((G22-TRAINING!$U$4)^2)/(2*(TRAINING!$U$9^2))) -> 1.0107562 | Y22: =(1/(SQRT(2*PI())*TRAINING!$V$8))*EXP(-((H22-TRAINING!$V$3)^2)/(2*(TRAINING!$V$8^2))) -> 0.031451241 | Z22: =(1/(SQRT(2*PI())*TRAINING!$V$9))*EXP(-((H22-TRAINING!$V$4)^2)/(2*(TRAINING!$V$9^2))) -> 0.024768154 | AA22: =PRODUCT(K22,M22,O22,Q22,S22,U22,W22,Y22)*TRAINING!$L$2 -> 1.3496071e-13 | AB22: =PRODUCT(L22,N22,P22,R22,T22,V22,X22,Z22)*TRAINING!$L$3 -> 3.7387822e-13 | AC22: =IF(AB22>AA22,1,0) -> 1 | AD22: =IF(I22=AC22,1,0) -> 0 | AG22: =IF(AND(AC22=1,I22=1),"TP",IF(AND(AC22=0,I22=0),"TN",IF(AND(AC22=1,I22=0),"FP","FN"))) -> FP
